Sending Message
Sending Message
Sending Message
Sending Message
Sending Message
Sending Message
Sending Message
Sending Message
Sending Message
Sending Message
Sending Message
Sending Message
Sending Message
Sending Message
Sending Message
Sending Message
Sending Message
Sending Message
Sending Message
Sending Message
Sending Message
Sending Message
Sending Message
Sending Message
Sending Message
Sending Message
Sending Message
Sending Message
Sending Message
Sending Message
Sending Message
Sending Message
Sending Message
Sending Message
Sending Message
Traceback (most recent call last):
  File "/usr/lib/python3/dist-packages/urllib3/connection.py", line 159, in _new_conn
    (self._dns_host, self.port), self.timeout, **extra_kw)
  File "/usr/lib/python3/dist-packages/urllib3/util/connection.py", line 57, in create_connection
    for res in socket.getaddrinfo(host, port, family, socket.SOCK_STREAM):
  File "/usr/lib/python3.7/socket.py", line 748, in getaddrinfo
    for res in _socket.getaddrinfo(host, port, family, type, proto, flags):
socket.gaierror: [Errno -3] Temporary failure in name resolution

During handling of the above exception, another exception occurred:

Traceback (most recent call last):
  File "/usr/lib/python3/dist-packages/urllib3/connectionpool.py", line 600, in urlopen
    chunked=chunked)
  File "/usr/lib/python3/dist-packages/urllib3/connectionpool.py", line 343, in _make_request
    self._validate_conn(conn)
  File "/usr/lib/python3/dist-packages/urllib3/connectionpool.py", line 841, in _validate_conn
    conn.connect()
  File "/usr/lib/python3/dist-packages/urllib3/connection.py", line 301, in connect
    conn = self._new_conn()
  File "/usr/lib/python3/dist-packages/urllib3/connection.py", line 168, in _new_conn
    self, "Failed to establish a new connection: %s" % e)
urllib3.exceptions.NewConnectionError: <urllib3.connection.VerifiedHTTPSConnection object at 0x7fe898615358>: Failed to establish a new connection: [Errno -3] Temporary failure in name resolution

During handling of the above exception, another exception occurred:

Traceback (most recent call last):
  File "/usr/lib/python3/dist-packages/requests/adapters.py", line 449, in send
    timeout=timeout
  File "/usr/lib/python3/dist-packages/urllib3/connectionpool.py", line 638, in urlopen
    _stacktrace=sys.exc_info()[2])
  File "/usr/lib/python3/dist-packages/urllib3/util/retry.py", line 398, in increment
    raise MaxRetryError(_pool, url, error or ResponseError(cause))
urllib3.exceptions.MaxRetryError: HTTPSConnectionPool(host='ll.thespacedevs.com', port=443): Max retries exceeded with url: /2.0.0/launch/upcoming?mode=list (Caused by NewConnectionError('<urllib3.connection.VerifiedHTTPSConnection object at 0x7fe898615358>: Failed to establish a new connection: [Errno -3] Temporary failure in name resolution'))

During handling of the above exception, another exception occurred:

Traceback (most recent call last):
  File "print_launches.py", line 6, in <module>
    import get_launches
  File "/home/finn/STM32-Discord-Bot/get_launches.py", line 91, in <module>
    update_launches()
  File "/home/finn/STM32-Discord-Bot/get_launches.py", line 87, in update_launches
    launch_data = get_launch_json()
  File "/home/finn/STM32-Discord-Bot/get_launches.py", line 18, in get_launch_json
    requestData = requests.get('https://ll.thespacedevs.com/2.0.0/launch/upcoming?mode=list')
  File "/usr/lib/python3/dist-packages/requests/api.py", line 75, in get
    return request('get', url, params=params, **kwargs)
  File "/usr/lib/python3/dist-packages/requests/api.py", line 60, in request
    return session.request(method=method, url=url, **kwargs)
  File "/usr/lib/python3/dist-packages/requests/sessions.py", line 533, in request
    resp = self.send(prep, **send_kwargs)
  File "/usr/lib/python3/dist-packages/requests/sessions.py", line 646, in send
    r = adapter.send(request, **kwargs)
  File "/usr/lib/python3/dist-packages/requests/adapters.py", line 516, in send
    raise ConnectionError(e, request=request)
requests.exceptions.ConnectionError: HTTPSConnectionPool(host='ll.thespacedevs.com', port=443): Max retries exceeded with url: /2.0.0/launch/upcoming?mode=list (Caused by NewConnectionError('<urllib3.connection.VerifiedHTTPSConnection object at 0x7fe898615358>: Failed to establish a new connection: [Errno -3] Temporary failure in name resolution'))
Traceback (most recent call last):
  File "/usr/lib/python3/dist-packages/urllib3/connection.py", line 159, in _new_conn
    (self._dns_host, self.port), self.timeout, **extra_kw)
  File "/usr/lib/python3/dist-packages/urllib3/util/connection.py", line 57, in create_connection
    for res in socket.getaddrinfo(host, port, family, socket.SOCK_STREAM):
  File "/usr/lib/python3.7/socket.py", line 748, in getaddrinfo
    for res in _socket.getaddrinfo(host, port, family, type, proto, flags):
socket.gaierror: [Errno -3] Temporary failure in name resolution

During handling of the above exception, another exception occurred:

Traceback (most recent call last):
  File "/usr/lib/python3/dist-packages/urllib3/connectionpool.py", line 600, in urlopen
    chunked=chunked)
  File "/usr/lib/python3/dist-packages/urllib3/connectionpool.py", line 343, in _make_request
    self._validate_conn(conn)
  File "/usr/lib/python3/dist-packages/urllib3/connectionpool.py", line 841, in _validate_conn
    conn.connect()
  File "/usr/lib/python3/dist-packages/urllib3/connection.py", line 301, in connect
    conn = self._new_conn()
  File "/usr/lib/python3/dist-packages/urllib3/connection.py", line 168, in _new_conn
    self, "Failed to establish a new connection: %s" % e)
urllib3.exceptions.NewConnectionError: <urllib3.connection.VerifiedHTTPSConnection object at 0x7f12ab4771d0>: Failed to establish a new connection: [Errno -3] Temporary failure in name resolution

During handling of the above exception, another exception occurred:

Traceback (most recent call last):
  File "/usr/lib/python3/dist-packages/requests/adapters.py", line 449, in send
    timeout=timeout
  File "/usr/lib/python3/dist-packages/urllib3/connectionpool.py", line 638, in urlopen
    _stacktrace=sys.exc_info()[2])
  File "/usr/lib/python3/dist-packages/urllib3/util/retry.py", line 398, in increment
    raise MaxRetryError(_pool, url, error or ResponseError(cause))
urllib3.exceptions.MaxRetryError: HTTPSConnectionPool(host='ll.thespacedevs.com', port=443): Max retries exceeded with url: /2.0.0/launch/upcoming?mode=list (Caused by NewConnectionError('<urllib3.connection.VerifiedHTTPSConnection object at 0x7f12ab4771d0>: Failed to establish a new connection: [Errno -3] Temporary failure in name resolution'))

During handling of the above exception, another exception occurred:

Traceback (most recent call last):
  File "print_launches.py", line 6, in <module>
    import get_launches
  File "/home/finn/STM32-Discord-Bot/get_launches.py", line 91, in <module>
    update_launches()
  File "/home/finn/STM32-Discord-Bot/get_launches.py", line 87, in update_launches
    launch_data = get_launch_json()
  File "/home/finn/STM32-Discord-Bot/get_launches.py", line 18, in get_launch_json
    requestData = requests.get('https://ll.thespacedevs.com/2.0.0/launch/upcoming?mode=list')
  File "/usr/lib/python3/dist-packages/requests/api.py", line 75, in get
    return request('get', url, params=params, **kwargs)
  File "/usr/lib/python3/dist-packages/requests/api.py", line 60, in request
    return session.request(method=method, url=url, **kwargs)
  File "/usr/lib/python3/dist-packages/requests/sessions.py", line 533, in request
    resp = self.send(prep, **send_kwargs)
  File "/usr/lib/python3/dist-packages/requests/sessions.py", line 646, in send
    r = adapter.send(request, **kwargs)
  File "/usr/lib/python3/dist-packages/requests/adapters.py", line 516, in send
    raise ConnectionError(e, request=request)
requests.exceptions.ConnectionError: HTTPSConnectionPool(host='ll.thespacedevs.com', port=443): Max retries exceeded with url: /2.0.0/launch/upcoming?mode=list (Caused by NewConnectionError('<urllib3.connection.VerifiedHTTPSConnection object at 0x7f12ab4771d0>: Failed to establish a new connection: [Errno -3] Temporary failure in name resolution'))
Traceback (most recent call last):
  File "/usr/lib/python3/dist-packages/urllib3/connection.py", line 159, in _new_conn
    (self._dns_host, self.port), self.timeout, **extra_kw)
  File "/usr/lib/python3/dist-packages/urllib3/util/connection.py", line 57, in create_connection
    for res in socket.getaddrinfo(host, port, family, socket.SOCK_STREAM):
  File "/usr/lib/python3.7/socket.py", line 748, in getaddrinfo
    for res in _socket.getaddrinfo(host, port, family, type, proto, flags):
socket.gaierror: [Errno -3] Temporary failure in name resolution

During handling of the above exception, another exception occurred:

Traceback (most recent call last):
  File "/usr/lib/python3/dist-packages/urllib3/connectionpool.py", line 600, in urlopen
    chunked=chunked)
  File "/usr/lib/python3/dist-packages/urllib3/connectionpool.py", line 343, in _make_request
    self._validate_conn(conn)
  File "/usr/lib/python3/dist-packages/urllib3/connectionpool.py", line 841, in _validate_conn
    conn.connect()
  File "/usr/lib/python3/dist-packages/urllib3/connection.py", line 301, in connect
    conn = self._new_conn()
  File "/usr/lib/python3/dist-packages/urllib3/connection.py", line 168, in _new_conn
    self, "Failed to establish a new connection: %s" % e)
urllib3.exceptions.NewConnectionError: <urllib3.connection.VerifiedHTTPSConnection object at 0x7fccf5fec278>: Failed to establish a new connection: [Errno -3] Temporary failure in name resolution

During handling of the above exception, another exception occurred:

Traceback (most recent call last):
  File "/usr/lib/python3/dist-packages/requests/adapters.py", line 449, in send
    timeout=timeout
  File "/usr/lib/python3/dist-packages/urllib3/connectionpool.py", line 638, in urlopen
    _stacktrace=sys.exc_info()[2])
  File "/usr/lib/python3/dist-packages/urllib3/util/retry.py", line 398, in increment
    raise MaxRetryError(_pool, url, error or ResponseError(cause))
urllib3.exceptions.MaxRetryError: HTTPSConnectionPool(host='ll.thespacedevs.com', port=443): Max retries exceeded with url: /2.0.0/launch/upcoming?mode=list (Caused by NewConnectionError('<urllib3.connection.VerifiedHTTPSConnection object at 0x7fccf5fec278>: Failed to establish a new connection: [Errno -3] Temporary failure in name resolution'))

During handling of the above exception, another exception occurred:

Traceback (most recent call last):
  File "print_launches.py", line 6, in <module>
    import get_launches
  File "/home/finn/STM32-Discord-Bot/get_launches.py", line 91, in <module>
    update_launches()
  File "/home/finn/STM32-Discord-Bot/get_launches.py", line 87, in update_launches
    launch_data = get_launch_json()
  File "/home/finn/STM32-Discord-Bot/get_launches.py", line 18, in get_launch_json
    requestData = requests.get('https://ll.thespacedevs.com/2.0.0/launch/upcoming?mode=list')
  File "/usr/lib/python3/dist-packages/requests/api.py", line 75, in get
    return request('get', url, params=params, **kwargs)
  File "/usr/lib/python3/dist-packages/requests/api.py", line 60, in request
    return session.request(method=method, url=url, **kwargs)
  File "/usr/lib/python3/dist-packages/requests/sessions.py", line 533, in request
    resp = self.send(prep, **send_kwargs)
  File "/usr/lib/python3/dist-packages/requests/sessions.py", line 646, in send
    r = adapter.send(request, **kwargs)
  File "/usr/lib/python3/dist-packages/requests/adapters.py", line 516, in send
    raise ConnectionError(e, request=request)
requests.exceptions.ConnectionError: HTTPSConnectionPool(host='ll.thespacedevs.com', port=443): Max retries exceeded with url: /2.0.0/launch/upcoming?mode=list (Caused by NewConnectionError('<urllib3.connection.VerifiedHTTPSConnection object at 0x7fccf5fec278>: Failed to establish a new connection: [Errno -3] Temporary failure in name resolution'))
Traceback (most recent call last):
  File "/usr/lib/python3/dist-packages/urllib3/connection.py", line 159, in _new_conn
    (self._dns_host, self.port), self.timeout, **extra_kw)
  File "/usr/lib/python3/dist-packages/urllib3/util/connection.py", line 57, in create_connection
    for res in socket.getaddrinfo(host, port, family, socket.SOCK_STREAM):
  File "/usr/lib/python3.7/socket.py", line 748, in getaddrinfo
    for res in _socket.getaddrinfo(host, port, family, type, proto, flags):
socket.gaierror: [Errno -3] Temporary failure in name resolution

During handling of the above exception, another exception occurred:

Traceback (most recent call last):
  File "/usr/lib/python3/dist-packages/urllib3/connectionpool.py", line 600, in urlopen
    chunked=chunked)
  File "/usr/lib/python3/dist-packages/urllib3/connectionpool.py", line 343, in _make_request
    self._validate_conn(conn)
  File "/usr/lib/python3/dist-packages/urllib3/connectionpool.py", line 841, in _validate_conn
    conn.connect()
  File "/usr/lib/python3/dist-packages/urllib3/connection.py", line 301, in connect
    conn = self._new_conn()
  File "/usr/lib/python3/dist-packages/urllib3/connection.py", line 168, in _new_conn
    self, "Failed to establish a new connection: %s" % e)
urllib3.exceptions.NewConnectionError: <urllib3.connection.VerifiedHTTPSConnection object at 0x7fc054d6f278>: Failed to establish a new connection: [Errno -3] Temporary failure in name resolution

During handling of the above exception, another exception occurred:

Traceback (most recent call last):
  File "/usr/lib/python3/dist-packages/requests/adapters.py", line 449, in send
    timeout=timeout
  File "/usr/lib/python3/dist-packages/urllib3/connectionpool.py", line 638, in urlopen
    _stacktrace=sys.exc_info()[2])
  File "/usr/lib/python3/dist-packages/urllib3/util/retry.py", line 398, in increment
    raise MaxRetryError(_pool, url, error or ResponseError(cause))
urllib3.exceptions.MaxRetryError: HTTPSConnectionPool(host='ll.thespacedevs.com', port=443): Max retries exceeded with url: /2.0.0/launch/upcoming?mode=list (Caused by NewConnectionError('<urllib3.connection.VerifiedHTTPSConnection object at 0x7fc054d6f278>: Failed to establish a new connection: [Errno -3] Temporary failure in name resolution'))

During handling of the above exception, another exception occurred:

Traceback (most recent call last):
  File "print_launches.py", line 6, in <module>
    import get_launches
  File "/home/finn/STM32-Discord-Bot/get_launches.py", line 91, in <module>
    update_launches()
  File "/home/finn/STM32-Discord-Bot/get_launches.py", line 87, in update_launches
    launch_data = get_launch_json()
  File "/home/finn/STM32-Discord-Bot/get_launches.py", line 18, in get_launch_json
    requestData = requests.get('https://ll.thespacedevs.com/2.0.0/launch/upcoming?mode=list')
  File "/usr/lib/python3/dist-packages/requests/api.py", line 75, in get
    return request('get', url, params=params, **kwargs)
  File "/usr/lib/python3/dist-packages/requests/api.py", line 60, in request
    return session.request(method=method, url=url, **kwargs)
  File "/usr/lib/python3/dist-packages/requests/sessions.py", line 533, in request
    resp = self.send(prep, **send_kwargs)
  File "/usr/lib/python3/dist-packages/requests/sessions.py", line 646, in send
    r = adapter.send(request, **kwargs)
  File "/usr/lib/python3/dist-packages/requests/adapters.py", line 516, in send
    raise ConnectionError(e, request=request)
requests.exceptions.ConnectionError: HTTPSConnectionPool(host='ll.thespacedevs.com', port=443): Max retries exceeded with url: /2.0.0/launch/upcoming?mode=list (Caused by NewConnectionError('<urllib3.connection.VerifiedHTTPSConnection object at 0x7fc054d6f278>: Failed to establish a new connection: [Errno -3] Temporary failure in name resolution'))
Sending Message
Sending Message
Traceback (most recent call last):
  File "/usr/lib/python3/dist-packages/urllib3/connection.py", line 159, in _new_conn
    (self._dns_host, self.port), self.timeout, **extra_kw)
  File "/usr/lib/python3/dist-packages/urllib3/util/connection.py", line 57, in create_connection
    for res in socket.getaddrinfo(host, port, family, socket.SOCK_STREAM):
  File "/usr/lib/python3.7/socket.py", line 748, in getaddrinfo
    for res in _socket.getaddrinfo(host, port, family, type, proto, flags):
socket.gaierror: [Errno -3] Temporary failure in name resolution

During handling of the above exception, another exception occurred:

Traceback (most recent call last):
  File "/usr/lib/python3/dist-packages/urllib3/connectionpool.py", line 600, in urlopen
    chunked=chunked)
  File "/usr/lib/python3/dist-packages/urllib3/connectionpool.py", line 343, in _make_request
    self._validate_conn(conn)
  File "/usr/lib/python3/dist-packages/urllib3/connectionpool.py", line 841, in _validate_conn
    conn.connect()
  File "/usr/lib/python3/dist-packages/urllib3/connection.py", line 301, in connect
    conn = self._new_conn()
  File "/usr/lib/python3/dist-packages/urllib3/connection.py", line 168, in _new_conn
    self, "Failed to establish a new connection: %s" % e)
urllib3.exceptions.NewConnectionError: <urllib3.connection.VerifiedHTTPSConnection object at 0x7fa6b1834198>: Failed to establish a new connection: [Errno -3] Temporary failure in name resolution

During handling of the above exception, another exception occurred:

Traceback (most recent call last):
  File "/usr/lib/python3/dist-packages/requests/adapters.py", line 449, in send
    timeout=timeout
  File "/usr/lib/python3/dist-packages/urllib3/connectionpool.py", line 638, in urlopen
    _stacktrace=sys.exc_info()[2])
  File "/usr/lib/python3/dist-packages/urllib3/util/retry.py", line 398, in increment
    raise MaxRetryError(_pool, url, error or ResponseError(cause))
urllib3.exceptions.MaxRetryError: HTTPSConnectionPool(host='ll.thespacedevs.com', port=443): Max retries exceeded with url: /2.0.0/launch/upcoming?mode=list (Caused by NewConnectionError('<urllib3.connection.VerifiedHTTPSConnection object at 0x7fa6b1834198>: Failed to establish a new connection: [Errno -3] Temporary failure in name resolution'))

During handling of the above exception, another exception occurred:

Traceback (most recent call last):
  File "print_launches.py", line 6, in <module>
    import get_launches
  File "/home/finn/STM32-Discord-Bot/get_launches.py", line 91, in <module>
    update_launches()
  File "/home/finn/STM32-Discord-Bot/get_launches.py", line 87, in update_launches
    launch_data = get_launch_json()
  File "/home/finn/STM32-Discord-Bot/get_launches.py", line 18, in get_launch_json
    requestData = requests.get('https://ll.thespacedevs.com/2.0.0/launch/upcoming?mode=list')
  File "/usr/lib/python3/dist-packages/requests/api.py", line 75, in get
    return request('get', url, params=params, **kwargs)
  File "/usr/lib/python3/dist-packages/requests/api.py", line 60, in request
    return session.request(method=method, url=url, **kwargs)
  File "/usr/lib/python3/dist-packages/requests/sessions.py", line 533, in request
    resp = self.send(prep, **send_kwargs)
  File "/usr/lib/python3/dist-packages/requests/sessions.py", line 646, in send
    r = adapter.send(request, **kwargs)
  File "/usr/lib/python3/dist-packages/requests/adapters.py", line 516, in send
    raise ConnectionError(e, request=request)
requests.exceptions.ConnectionError: HTTPSConnectionPool(host='ll.thespacedevs.com', port=443): Max retries exceeded with url: /2.0.0/launch/upcoming?mode=list (Caused by NewConnectionError('<urllib3.connection.VerifiedHTTPSConnection object at 0x7fa6b1834198>: Failed to establish a new connection: [Errno -3] Temporary failure in name resolution'))
Traceback (most recent call last):
  File "/usr/lib/python3/dist-packages/urllib3/connection.py", line 159, in _new_conn
    (self._dns_host, self.port), self.timeout, **extra_kw)
  File "/usr/lib/python3/dist-packages/urllib3/util/connection.py", line 57, in create_connection
    for res in socket.getaddrinfo(host, port, family, socket.SOCK_STREAM):
  File "/usr/lib/python3.7/socket.py", line 748, in getaddrinfo
    for res in _socket.getaddrinfo(host, port, family, type, proto, flags):
socket.gaierror: [Errno -3] Temporary failure in name resolution

During handling of the above exception, another exception occurred:

Traceback (most recent call last):
  File "/usr/lib/python3/dist-packages/urllib3/connectionpool.py", line 600, in urlopen
    chunked=chunked)
  File "/usr/lib/python3/dist-packages/urllib3/connectionpool.py", line 343, in _make_request
    self._validate_conn(conn)
  File "/usr/lib/python3/dist-packages/urllib3/connectionpool.py", line 841, in _validate_conn
    conn.connect()
  File "/usr/lib/python3/dist-packages/urllib3/connection.py", line 301, in connect
    conn = self._new_conn()
  File "/usr/lib/python3/dist-packages/urllib3/connection.py", line 168, in _new_conn
    self, "Failed to establish a new connection: %s" % e)
urllib3.exceptions.NewConnectionError: <urllib3.connection.VerifiedHTTPSConnection object at 0x7ffb8f720160>: Failed to establish a new connection: [Errno -3] Temporary failure in name resolution

During handling of the above exception, another exception occurred:

Traceback (most recent call last):
  File "/usr/lib/python3/dist-packages/requests/adapters.py", line 449, in send
    timeout=timeout
  File "/usr/lib/python3/dist-packages/urllib3/connectionpool.py", line 638, in urlopen
    _stacktrace=sys.exc_info()[2])
  File "/usr/lib/python3/dist-packages/urllib3/util/retry.py", line 398, in increment
    raise MaxRetryError(_pool, url, error or ResponseError(cause))
urllib3.exceptions.MaxRetryError: HTTPSConnectionPool(host='ll.thespacedevs.com', port=443): Max retries exceeded with url: /2.0.0/launch/upcoming?mode=list (Caused by NewConnectionError('<urllib3.connection.VerifiedHTTPSConnection object at 0x7ffb8f720160>: Failed to establish a new connection: [Errno -3] Temporary failure in name resolution'))

During handling of the above exception, another exception occurred:

Traceback (most recent call last):
  File "print_launches.py", line 6, in <module>
    import get_launches
  File "/home/finn/STM32-Discord-Bot/get_launches.py", line 91, in <module>
    update_launches()
  File "/home/finn/STM32-Discord-Bot/get_launches.py", line 87, in update_launches
    launch_data = get_launch_json()
  File "/home/finn/STM32-Discord-Bot/get_launches.py", line 18, in get_launch_json
    requestData = requests.get('https://ll.thespacedevs.com/2.0.0/launch/upcoming?mode=list')
  File "/usr/lib/python3/dist-packages/requests/api.py", line 75, in get
    return request('get', url, params=params, **kwargs)
  File "/usr/lib/python3/dist-packages/requests/api.py", line 60, in request
    return session.request(method=method, url=url, **kwargs)
  File "/usr/lib/python3/dist-packages/requests/sessions.py", line 533, in request
    resp = self.send(prep, **send_kwargs)
  File "/usr/lib/python3/dist-packages/requests/sessions.py", line 646, in send
    r = adapter.send(request, **kwargs)
  File "/usr/lib/python3/dist-packages/requests/adapters.py", line 516, in send
    raise ConnectionError(e, request=request)
requests.exceptions.ConnectionError: HTTPSConnectionPool(host='ll.thespacedevs.com', port=443): Max retries exceeded with url: /2.0.0/launch/upcoming?mode=list (Caused by NewConnectionError('<urllib3.connection.VerifiedHTTPSConnection object at 0x7ffb8f720160>: Failed to establish a new connection: [Errno -3] Temporary failure in name resolution'))
Traceback (most recent call last):
  File "/usr/lib/python3/dist-packages/urllib3/connection.py", line 159, in _new_conn
    (self._dns_host, self.port), self.timeout, **extra_kw)
  File "/usr/lib/python3/dist-packages/urllib3/util/connection.py", line 57, in create_connection
    for res in socket.getaddrinfo(host, port, family, socket.SOCK_STREAM):
  File "/usr/lib/python3.7/socket.py", line 748, in getaddrinfo
    for res in _socket.getaddrinfo(host, port, family, type, proto, flags):
socket.gaierror: [Errno -3] Temporary failure in name resolution

During handling of the above exception, another exception occurred:

Traceback (most recent call last):
  File "/usr/lib/python3/dist-packages/urllib3/connectionpool.py", line 600, in urlopen
    chunked=chunked)
  File "/usr/lib/python3/dist-packages/urllib3/connectionpool.py", line 343, in _make_request
    self._validate_conn(conn)
  File "/usr/lib/python3/dist-packages/urllib3/connectionpool.py", line 841, in _validate_conn
    conn.connect()
  File "/usr/lib/python3/dist-packages/urllib3/connection.py", line 301, in connect
    conn = self._new_conn()
  File "/usr/lib/python3/dist-packages/urllib3/connection.py", line 168, in _new_conn
    self, "Failed to establish a new connection: %s" % e)
urllib3.exceptions.NewConnectionError: <urllib3.connection.VerifiedHTTPSConnection object at 0x7f760f454160>: Failed to establish a new connection: [Errno -3] Temporary failure in name resolution

During handling of the above exception, another exception occurred:

Traceback (most recent call last):
  File "/usr/lib/python3/dist-packages/requests/adapters.py", line 449, in send
    timeout=timeout
  File "/usr/lib/python3/dist-packages/urllib3/connectionpool.py", line 638, in urlopen
    _stacktrace=sys.exc_info()[2])
  File "/usr/lib/python3/dist-packages/urllib3/util/retry.py", line 398, in increment
    raise MaxRetryError(_pool, url, error or ResponseError(cause))
urllib3.exceptions.MaxRetryError: HTTPSConnectionPool(host='ll.thespacedevs.com', port=443): Max retries exceeded with url: /2.0.0/launch/upcoming?mode=list (Caused by NewConnectionError('<urllib3.connection.VerifiedHTTPSConnection object at 0x7f760f454160>: Failed to establish a new connection: [Errno -3] Temporary failure in name resolution'))

During handling of the above exception, another exception occurred:

Traceback (most recent call last):
  File "print_launches.py", line 6, in <module>
    import get_launches
  File "/home/finn/STM32-Discord-Bot/get_launches.py", line 91, in <module>
    update_launches()
  File "/home/finn/STM32-Discord-Bot/get_launches.py", line 87, in update_launches
    launch_data = get_launch_json()
  File "/home/finn/STM32-Discord-Bot/get_launches.py", line 18, in get_launch_json
    requestData = requests.get('https://ll.thespacedevs.com/2.0.0/launch/upcoming?mode=list')
  File "/usr/lib/python3/dist-packages/requests/api.py", line 75, in get
    return request('get', url, params=params, **kwargs)
  File "/usr/lib/python3/dist-packages/requests/api.py", line 60, in request
    return session.request(method=method, url=url, **kwargs)
  File "/usr/lib/python3/dist-packages/requests/sessions.py", line 533, in request
    resp = self.send(prep, **send_kwargs)
  File "/usr/lib/python3/dist-packages/requests/sessions.py", line 646, in send
    r = adapter.send(request, **kwargs)
  File "/usr/lib/python3/dist-packages/requests/adapters.py", line 516, in send
    raise ConnectionError(e, request=request)
requests.exceptions.ConnectionError: HTTPSConnectionPool(host='ll.thespacedevs.com', port=443): Max retries exceeded with url: /2.0.0/launch/upcoming?mode=list (Caused by NewConnectionError('<urllib3.connection.VerifiedHTTPSConnection object at 0x7f760f454160>: Failed to establish a new connection: [Errno -3] Temporary failure in name resolution'))
Sending Message
Sending Message
Sending Message
Sending Message
Sending Message
Sending Message
Sending Message
Sending Message
Sending Message
Sending Message
Sending Message
Sending Message
Sending Message
Sending Message
Sending Message
Sending Message
Sending Message
Sending Message
Traceback (most recent call last):
  File "/usr/lib/python3/dist-packages/urllib3/connection.py", line 159, in _new_conn
    (self._dns_host, self.port), self.timeout, **extra_kw)
  File "/usr/lib/python3/dist-packages/urllib3/util/connection.py", line 57, in create_connection
    for res in socket.getaddrinfo(host, port, family, socket.SOCK_STREAM):
  File "/usr/lib/python3.7/socket.py", line 748, in getaddrinfo
    for res in _socket.getaddrinfo(host, port, family, type, proto, flags):
socket.gaierror: [Errno -3] Temporary failure in name resolution

During handling of the above exception, another exception occurred:

Traceback (most recent call last):
  File "/usr/lib/python3/dist-packages/urllib3/connectionpool.py", line 600, in urlopen
    chunked=chunked)
  File "/usr/lib/python3/dist-packages/urllib3/connectionpool.py", line 343, in _make_request
    self._validate_conn(conn)
  File "/usr/lib/python3/dist-packages/urllib3/connectionpool.py", line 841, in _validate_conn
    conn.connect()
  File "/usr/lib/python3/dist-packages/urllib3/connection.py", line 301, in connect
    conn = self._new_conn()
  File "/usr/lib/python3/dist-packages/urllib3/connection.py", line 168, in _new_conn
    self, "Failed to establish a new connection: %s" % e)
urllib3.exceptions.NewConnectionError: <urllib3.connection.VerifiedHTTPSConnection object at 0x7f0156780080>: Failed to establish a new connection: [Errno -3] Temporary failure in name resolution

During handling of the above exception, another exception occurred:

Traceback (most recent call last):
  File "/usr/lib/python3/dist-packages/requests/adapters.py", line 449, in send
    timeout=timeout
  File "/usr/lib/python3/dist-packages/urllib3/connectionpool.py", line 638, in urlopen
    _stacktrace=sys.exc_info()[2])
  File "/usr/lib/python3/dist-packages/urllib3/util/retry.py", line 398, in increment
    raise MaxRetryError(_pool, url, error or ResponseError(cause))
urllib3.exceptions.MaxRetryError: HTTPSConnectionPool(host='ll.thespacedevs.com', port=443): Max retries exceeded with url: /2.0.0/launch/upcoming?mode=list (Caused by NewConnectionError('<urllib3.connection.VerifiedHTTPSConnection object at 0x7f0156780080>: Failed to establish a new connection: [Errno -3] Temporary failure in name resolution'))

During handling of the above exception, another exception occurred:

Traceback (most recent call last):
  File "print_launches.py", line 6, in <module>
    import get_launches
  File "/home/finn/STM32-Discord-Bot/get_launches.py", line 91, in <module>
    update_launches()
  File "/home/finn/STM32-Discord-Bot/get_launches.py", line 87, in update_launches
    launch_data = get_launch_json()
  File "/home/finn/STM32-Discord-Bot/get_launches.py", line 18, in get_launch_json
    requestData = requests.get('https://ll.thespacedevs.com/2.0.0/launch/upcoming?mode=list')
  File "/usr/lib/python3/dist-packages/requests/api.py", line 75, in get
    return request('get', url, params=params, **kwargs)
  File "/usr/lib/python3/dist-packages/requests/api.py", line 60, in request
    return session.request(method=method, url=url, **kwargs)
  File "/usr/lib/python3/dist-packages/requests/sessions.py", line 533, in request
    resp = self.send(prep, **send_kwargs)
  File "/usr/lib/python3/dist-packages/requests/sessions.py", line 646, in send
    r = adapter.send(request, **kwargs)
  File "/usr/lib/python3/dist-packages/requests/adapters.py", line 516, in send
    raise ConnectionError(e, request=request)
requests.exceptions.ConnectionError: HTTPSConnectionPool(host='ll.thespacedevs.com', port=443): Max retries exceeded with url: /2.0.0/launch/upcoming?mode=list (Caused by NewConnectionError('<urllib3.connection.VerifiedHTTPSConnection object at 0x7f0156780080>: Failed to establish a new connection: [Errno -3] Temporary failure in name resolution'))
Sending Message
Sending Message
Sending Message
Sending Message
Sending Message
Sending Message
Sending Message
Sending Message
Traceback (most recent call last):
  File "/usr/lib/python3/dist-packages/urllib3/connection.py", line 159, in _new_conn
    (self._dns_host, self.port), self.timeout, **extra_kw)
  File "/usr/lib/python3/dist-packages/urllib3/util/connection.py", line 57, in create_connection
    for res in socket.getaddrinfo(host, port, family, socket.SOCK_STREAM):
  File "/usr/lib/python3.7/socket.py", line 748, in getaddrinfo
    for res in _socket.getaddrinfo(host, port, family, type, proto, flags):
socket.gaierror: [Errno -3] Temporary failure in name resolution

During handling of the above exception, another exception occurred:

Traceback (most recent call last):
  File "/usr/lib/python3/dist-packages/urllib3/connectionpool.py", line 600, in urlopen
    chunked=chunked)
  File "/usr/lib/python3/dist-packages/urllib3/connectionpool.py", line 343, in _make_request
    self._validate_conn(conn)
  File "/usr/lib/python3/dist-packages/urllib3/connectionpool.py", line 841, in _validate_conn
    conn.connect()
  File "/usr/lib/python3/dist-packages/urllib3/connection.py", line 301, in connect
    conn = self._new_conn()
  File "/usr/lib/python3/dist-packages/urllib3/connection.py", line 168, in _new_conn
    self, "Failed to establish a new connection: %s" % e)
urllib3.exceptions.NewConnectionError: <urllib3.connection.VerifiedHTTPSConnection object at 0x7ff25e661320>: Failed to establish a new connection: [Errno -3] Temporary failure in name resolution

During handling of the above exception, another exception occurred:

Traceback (most recent call last):
  File "/usr/lib/python3/dist-packages/requests/adapters.py", line 449, in send
    timeout=timeout
  File "/usr/lib/python3/dist-packages/urllib3/connectionpool.py", line 638, in urlopen
    _stacktrace=sys.exc_info()[2])
  File "/usr/lib/python3/dist-packages/urllib3/util/retry.py", line 398, in increment
    raise MaxRetryError(_pool, url, error or ResponseError(cause))
urllib3.exceptions.MaxRetryError: HTTPSConnectionPool(host='ll.thespacedevs.com', port=443): Max retries exceeded with url: /2.0.0/launch/upcoming?mode=list (Caused by NewConnectionError('<urllib3.connection.VerifiedHTTPSConnection object at 0x7ff25e661320>: Failed to establish a new connection: [Errno -3] Temporary failure in name resolution'))

During handling of the above exception, another exception occurred:

Traceback (most recent call last):
  File "print_launches.py", line 6, in <module>
    import get_launches
  File "/home/finn/STM32-Discord-Bot/get_launches.py", line 91, in <module>
    update_launches()
  File "/home/finn/STM32-Discord-Bot/get_launches.py", line 87, in update_launches
    launch_data = get_launch_json()
  File "/home/finn/STM32-Discord-Bot/get_launches.py", line 18, in get_launch_json
    requestData = requests.get('https://ll.thespacedevs.com/2.0.0/launch/upcoming?mode=list')
  File "/usr/lib/python3/dist-packages/requests/api.py", line 75, in get
    return request('get', url, params=params, **kwargs)
  File "/usr/lib/python3/dist-packages/requests/api.py", line 60, in request
    return session.request(method=method, url=url, **kwargs)
  File "/usr/lib/python3/dist-packages/requests/sessions.py", line 533, in request
    resp = self.send(prep, **send_kwargs)
  File "/usr/lib/python3/dist-packages/requests/sessions.py", line 646, in send
    r = adapter.send(request, **kwargs)
  File "/usr/lib/python3/dist-packages/requests/adapters.py", line 516, in send
    raise ConnectionError(e, request=request)
requests.exceptions.ConnectionError: HTTPSConnectionPool(host='ll.thespacedevs.com', port=443): Max retries exceeded with url: /2.0.0/launch/upcoming?mode=list (Caused by NewConnectionError('<urllib3.connection.VerifiedHTTPSConnection object at 0x7ff25e661320>: Failed to establish a new connection: [Errno -3] Temporary failure in name resolution'))
Sending Message
Sending Message
Sending Message
Sending Message
Sending Message
Sending Message
Sending Message
Sending Message
Sending Message
Sending Message
Sending Message
Sending Message
Sending Message
Sending Message
Sending Message
Sending Message
Sending Message
Sending Message
Sending Message
Sending Message
Sending Message
Sending Message
Sending Message
Sending Message
Sending Message
Sending Message
Traceback (most recent call last):
  File "/usr/lib/python3/dist-packages/urllib3/connectionpool.py", line 600, in urlopen
    chunked=chunked)
  File "/usr/lib/python3/dist-packages/urllib3/connectionpool.py", line 384, in _make_request
    six.raise_from(e, None)
  File "<string>", line 3, in raise_from
  File "/usr/lib/python3/dist-packages/urllib3/connectionpool.py", line 380, in _make_request
    httplib_response = conn.getresponse()
  File "/usr/lib/python3.7/http/client.py", line 1352, in getresponse
    response.begin()
  File "/usr/lib/python3.7/http/client.py", line 310, in begin
    version, status, reason = self._read_status()
  File "/usr/lib/python3.7/http/client.py", line 271, in _read_status
    line = str(self.fp.readline(_MAXLINE + 1), "iso-8859-1")
  File "/usr/lib/python3.7/socket.py", line 589, in readinto
    return self._sock.recv_into(b)
  File "/usr/lib/python3.7/ssl.py", line 1052, in recv_into
    return self.read(nbytes, buffer)
  File "/usr/lib/python3.7/ssl.py", line 911, in read
    return self._sslobj.read(len, buffer)
ConnectionResetError: [Errno 104] Connection reset by peer

During handling of the above exception, another exception occurred:

Traceback (most recent call last):
  File "/usr/lib/python3/dist-packages/requests/adapters.py", line 449, in send
    timeout=timeout
  File "/usr/lib/python3/dist-packages/urllib3/connectionpool.py", line 638, in urlopen
    _stacktrace=sys.exc_info()[2])
  File "/usr/lib/python3/dist-packages/urllib3/util/retry.py", line 367, in increment
    raise six.reraise(type(error), error, _stacktrace)
  File "/usr/lib/python3/dist-packages/six.py", line 692, in reraise
    raise value.with_traceback(tb)
  File "/usr/lib/python3/dist-packages/urllib3/connectionpool.py", line 600, in urlopen
    chunked=chunked)
  File "/usr/lib/python3/dist-packages/urllib3/connectionpool.py", line 384, in _make_request
    six.raise_from(e, None)
  File "<string>", line 3, in raise_from
  File "/usr/lib/python3/dist-packages/urllib3/connectionpool.py", line 380, in _make_request
    httplib_response = conn.getresponse()
  File "/usr/lib/python3.7/http/client.py", line 1352, in getresponse
    response.begin()
  File "/usr/lib/python3.7/http/client.py", line 310, in begin
    version, status, reason = self._read_status()
  File "/usr/lib/python3.7/http/client.py", line 271, in _read_status
    line = str(self.fp.readline(_MAXLINE + 1), "iso-8859-1")
  File "/usr/lib/python3.7/socket.py", line 589, in readinto
    return self._sock.recv_into(b)
  File "/usr/lib/python3.7/ssl.py", line 1052, in recv_into
    return self.read(nbytes, buffer)
  File "/usr/lib/python3.7/ssl.py", line 911, in read
    return self._sslobj.read(len, buffer)
urllib3.exceptions.ProtocolError: ('Connection aborted.', ConnectionResetError(104, 'Connection reset by peer'))

During handling of the above exception, another exception occurred:

Traceback (most recent call last):
  File "print_launches.py", line 6, in <module>
    import get_launches
  File "/home/finn/STM32-Discord-Bot/get_launches.py", line 91, in <module>
    update_launches()
  File "/home/finn/STM32-Discord-Bot/get_launches.py", line 87, in update_launches
    launch_data = get_launch_json()
  File "/home/finn/STM32-Discord-Bot/get_launches.py", line 18, in get_launch_json
    requestData = requests.get('https://ll.thespacedevs.com/2.0.0/launch/upcoming?mode=list')
  File "/usr/lib/python3/dist-packages/requests/api.py", line 75, in get
    return request('get', url, params=params, **kwargs)
  File "/usr/lib/python3/dist-packages/requests/api.py", line 60, in request
    return session.request(method=method, url=url, **kwargs)
  File "/usr/lib/python3/dist-packages/requests/sessions.py", line 533, in request
    resp = self.send(prep, **send_kwargs)
  File "/usr/lib/python3/dist-packages/requests/sessions.py", line 668, in send
    history = [resp for resp in gen] if allow_redirects else []
  File "/usr/lib/python3/dist-packages/requests/sessions.py", line 668, in <listcomp>
    history = [resp for resp in gen] if allow_redirects else []
  File "/usr/lib/python3/dist-packages/requests/sessions.py", line 247, in resolve_redirects
    **adapter_kwargs
  File "/usr/lib/python3/dist-packages/requests/sessions.py", line 646, in send
    r = adapter.send(request, **kwargs)
  File "/usr/lib/python3/dist-packages/requests/adapters.py", line 498, in send
    raise ConnectionError(err, request=request)
requests.exceptions.ConnectionError: ('Connection aborted.', ConnectionResetError(104, 'Connection reset by peer'))
Sending Message
Sending Message
Sending Message
Sending Message
Sending Message
Sending Message
Sending Message
Sending Message
Sending Message
Sending Message
Traceback (most recent call last):
  File "/usr/lib/python3/dist-packages/urllib3/connection.py", line 159, in _new_conn
    (self._dns_host, self.port), self.timeout, **extra_kw)
  File "/usr/lib/python3/dist-packages/urllib3/util/connection.py", line 57, in create_connection
    for res in socket.getaddrinfo(host, port, family, socket.SOCK_STREAM):
  File "/usr/lib/python3.7/socket.py", line 748, in getaddrinfo
    for res in _socket.getaddrinfo(host, port, family, type, proto, flags):
socket.gaierror: [Errno -3] Temporary failure in name resolution

During handling of the above exception, another exception occurred:

Traceback (most recent call last):
  File "/usr/lib/python3/dist-packages/urllib3/connectionpool.py", line 600, in urlopen
    chunked=chunked)
  File "/usr/lib/python3/dist-packages/urllib3/connectionpool.py", line 343, in _make_request
    self._validate_conn(conn)
  File "/usr/lib/python3/dist-packages/urllib3/connectionpool.py", line 841, in _validate_conn
    conn.connect()
  File "/usr/lib/python3/dist-packages/urllib3/connection.py", line 301, in connect
    conn = self._new_conn()
  File "/usr/lib/python3/dist-packages/urllib3/connection.py", line 168, in _new_conn
    self, "Failed to establish a new connection: %s" % e)
urllib3.exceptions.NewConnectionError: <urllib3.connection.VerifiedHTTPSConnection object at 0x7f6e0a87d438>: Failed to establish a new connection: [Errno -3] Temporary failure in name resolution

During handling of the above exception, another exception occurred:

Traceback (most recent call last):
  File "/usr/lib/python3/dist-packages/requests/adapters.py", line 449, in send
    timeout=timeout
  File "/usr/lib/python3/dist-packages/urllib3/connectionpool.py", line 638, in urlopen
    _stacktrace=sys.exc_info()[2])
  File "/usr/lib/python3/dist-packages/urllib3/util/retry.py", line 398, in increment
    raise MaxRetryError(_pool, url, error or ResponseError(cause))
urllib3.exceptions.MaxRetryError: HTTPSConnectionPool(host='ll.thespacedevs.com', port=443): Max retries exceeded with url: /2.0.0/launch/upcoming?mode=list (Caused by NewConnectionError('<urllib3.connection.VerifiedHTTPSConnection object at 0x7f6e0a87d438>: Failed to establish a new connection: [Errno -3] Temporary failure in name resolution'))

During handling of the above exception, another exception occurred:

Traceback (most recent call last):
  File "print_launches.py", line 6, in <module>
    import get_launches
  File "/home/finn/STM32-Discord-Bot/get_launches.py", line 91, in <module>
    update_launches()
  File "/home/finn/STM32-Discord-Bot/get_launches.py", line 87, in update_launches
    launch_data = get_launch_json()
  File "/home/finn/STM32-Discord-Bot/get_launches.py", line 18, in get_launch_json
    requestData = requests.get('https://ll.thespacedevs.com/2.0.0/launch/upcoming?mode=list')
  File "/usr/lib/python3/dist-packages/requests/api.py", line 75, in get
    return request('get', url, params=params, **kwargs)
  File "/usr/lib/python3/dist-packages/requests/api.py", line 60, in request
    return session.request(method=method, url=url, **kwargs)
  File "/usr/lib/python3/dist-packages/requests/sessions.py", line 533, in request
    resp = self.send(prep, **send_kwargs)
  File "/usr/lib/python3/dist-packages/requests/sessions.py", line 646, in send
    r = adapter.send(request, **kwargs)
  File "/usr/lib/python3/dist-packages/requests/adapters.py", line 516, in send
    raise ConnectionError(e, request=request)
requests.exceptions.ConnectionError: HTTPSConnectionPool(host='ll.thespacedevs.com', port=443): Max retries exceeded with url: /2.0.0/launch/upcoming?mode=list (Caused by NewConnectionError('<urllib3.connection.VerifiedHTTPSConnection object at 0x7f6e0a87d438>: Failed to establish a new connection: [Errno -3] Temporary failure in name resolution'))
Traceback (most recent call last):
  File "/usr/lib/python3/dist-packages/urllib3/connection.py", line 159, in _new_conn
    (self._dns_host, self.port), self.timeout, **extra_kw)
  File "/usr/lib/python3/dist-packages/urllib3/util/connection.py", line 57, in create_connection
    for res in socket.getaddrinfo(host, port, family, socket.SOCK_STREAM):
  File "/usr/lib/python3.7/socket.py", line 748, in getaddrinfo
    for res in _socket.getaddrinfo(host, port, family, type, proto, flags):
socket.gaierror: [Errno -3] Temporary failure in name resolution

During handling of the above exception, another exception occurred:

Traceback (most recent call last):
  File "/usr/lib/python3/dist-packages/urllib3/connectionpool.py", line 600, in urlopen
    chunked=chunked)
  File "/usr/lib/python3/dist-packages/urllib3/connectionpool.py", line 343, in _make_request
    self._validate_conn(conn)
  File "/usr/lib/python3/dist-packages/urllib3/connectionpool.py", line 841, in _validate_conn
    conn.connect()
  File "/usr/lib/python3/dist-packages/urllib3/connection.py", line 301, in connect
    conn = self._new_conn()
  File "/usr/lib/python3/dist-packages/urllib3/connection.py", line 168, in _new_conn
    self, "Failed to establish a new connection: %s" % e)
urllib3.exceptions.NewConnectionError: <urllib3.connection.VerifiedHTTPSConnection object at 0x7feb74c892b0>: Failed to establish a new connection: [Errno -3] Temporary failure in name resolution

During handling of the above exception, another exception occurred:

Traceback (most recent call last):
  File "/usr/lib/python3/dist-packages/requests/adapters.py", line 449, in send
    timeout=timeout
  File "/usr/lib/python3/dist-packages/urllib3/connectionpool.py", line 638, in urlopen
    _stacktrace=sys.exc_info()[2])
  File "/usr/lib/python3/dist-packages/urllib3/util/retry.py", line 398, in increment
    raise MaxRetryError(_pool, url, error or ResponseError(cause))
urllib3.exceptions.MaxRetryError: HTTPSConnectionPool(host='ll.thespacedevs.com', port=443): Max retries exceeded with url: /2.0.0/launch/upcoming?mode=list (Caused by NewConnectionError('<urllib3.connection.VerifiedHTTPSConnection object at 0x7feb74c892b0>: Failed to establish a new connection: [Errno -3] Temporary failure in name resolution'))

During handling of the above exception, another exception occurred:

Traceback (most recent call last):
  File "print_launches.py", line 6, in <module>
    import get_launches
  File "/home/finn/STM32-Discord-Bot/get_launches.py", line 91, in <module>
    update_launches()
  File "/home/finn/STM32-Discord-Bot/get_launches.py", line 87, in update_launches
    launch_data = get_launch_json()
  File "/home/finn/STM32-Discord-Bot/get_launches.py", line 18, in get_launch_json
    requestData = requests.get('https://ll.thespacedevs.com/2.0.0/launch/upcoming?mode=list')
  File "/usr/lib/python3/dist-packages/requests/api.py", line 75, in get
    return request('get', url, params=params, **kwargs)
  File "/usr/lib/python3/dist-packages/requests/api.py", line 60, in request
    return session.request(method=method, url=url, **kwargs)
  File "/usr/lib/python3/dist-packages/requests/sessions.py", line 533, in request
    resp = self.send(prep, **send_kwargs)
  File "/usr/lib/python3/dist-packages/requests/sessions.py", line 646, in send
    r = adapter.send(request, **kwargs)
  File "/usr/lib/python3/dist-packages/requests/adapters.py", line 516, in send
    raise ConnectionError(e, request=request)
requests.exceptions.ConnectionError: HTTPSConnectionPool(host='ll.thespacedevs.com', port=443): Max retries exceeded with url: /2.0.0/launch/upcoming?mode=list (Caused by NewConnectionError('<urllib3.connection.VerifiedHTTPSConnection object at 0x7feb74c892b0>: Failed to establish a new connection: [Errno -3] Temporary failure in name resolution'))
Traceback (most recent call last):
  File "/usr/lib/python3/dist-packages/urllib3/connection.py", line 159, in _new_conn
    (self._dns_host, self.port), self.timeout, **extra_kw)
  File "/usr/lib/python3/dist-packages/urllib3/util/connection.py", line 57, in create_connection
    for res in socket.getaddrinfo(host, port, family, socket.SOCK_STREAM):
  File "/usr/lib/python3.7/socket.py", line 748, in getaddrinfo
    for res in _socket.getaddrinfo(host, port, family, type, proto, flags):
socket.gaierror: [Errno -3] Temporary failure in name resolution

During handling of the above exception, another exception occurred:

Traceback (most recent call last):
  File "/usr/lib/python3/dist-packages/urllib3/connectionpool.py", line 600, in urlopen
    chunked=chunked)
  File "/usr/lib/python3/dist-packages/urllib3/connectionpool.py", line 343, in _make_request
    self._validate_conn(conn)
  File "/usr/lib/python3/dist-packages/urllib3/connectionpool.py", line 841, in _validate_conn
    conn.connect()
  File "/usr/lib/python3/dist-packages/urllib3/connection.py", line 301, in connect
    conn = self._new_conn()
  File "/usr/lib/python3/dist-packages/urllib3/connection.py", line 168, in _new_conn
    self, "Failed to establish a new connection: %s" % e)
urllib3.exceptions.NewConnectionError: <urllib3.connection.VerifiedHTTPSConnection object at 0x7fe9e3061320>: Failed to establish a new connection: [Errno -3] Temporary failure in name resolution

During handling of the above exception, another exception occurred:

Traceback (most recent call last):
  File "/usr/lib/python3/dist-packages/requests/adapters.py", line 449, in send
    timeout=timeout
  File "/usr/lib/python3/dist-packages/urllib3/connectionpool.py", line 638, in urlopen
    _stacktrace=sys.exc_info()[2])
  File "/usr/lib/python3/dist-packages/urllib3/util/retry.py", line 398, in increment
    raise MaxRetryError(_pool, url, error or ResponseError(cause))
urllib3.exceptions.MaxRetryError: HTTPSConnectionPool(host='ll.thespacedevs.com', port=443): Max retries exceeded with url: /2.0.0/launch/upcoming?mode=list (Caused by NewConnectionError('<urllib3.connection.VerifiedHTTPSConnection object at 0x7fe9e3061320>: Failed to establish a new connection: [Errno -3] Temporary failure in name resolution'))

During handling of the above exception, another exception occurred:

Traceback (most recent call last):
  File "print_launches.py", line 6, in <module>
    import get_launches
  File "/home/finn/STM32-Discord-Bot/get_launches.py", line 91, in <module>
    update_launches()
  File "/home/finn/STM32-Discord-Bot/get_launches.py", line 87, in update_launches
    launch_data = get_launch_json()
  File "/home/finn/STM32-Discord-Bot/get_launches.py", line 18, in get_launch_json
    requestData = requests.get('https://ll.thespacedevs.com/2.0.0/launch/upcoming?mode=list')
  File "/usr/lib/python3/dist-packages/requests/api.py", line 75, in get
    return request('get', url, params=params, **kwargs)
  File "/usr/lib/python3/dist-packages/requests/api.py", line 60, in request
    return session.request(method=method, url=url, **kwargs)
  File "/usr/lib/python3/dist-packages/requests/sessions.py", line 533, in request
    resp = self.send(prep, **send_kwargs)
  File "/usr/lib/python3/dist-packages/requests/sessions.py", line 646, in send
    r = adapter.send(request, **kwargs)
  File "/usr/lib/python3/dist-packages/requests/adapters.py", line 516, in send
    raise ConnectionError(e, request=request)
requests.exceptions.ConnectionError: HTTPSConnectionPool(host='ll.thespacedevs.com', port=443): Max retries exceeded with url: /2.0.0/launch/upcoming?mode=list (Caused by NewConnectionError('<urllib3.connection.VerifiedHTTPSConnection object at 0x7fe9e3061320>: Failed to establish a new connection: [Errno -3] Temporary failure in name resolution'))
Sending Message
Sending Message
Sending Message
Sending Message
Sending Message
Sending Message
Sending Message
Sending Message
Sending Message
Sending Message
Sending Message
Sending Message
Sending Message
Sending Message
Sending Message
Sending Message
Sending Message
Sending Message
Sending Message
Sending Message
Sending Message
Sending Message
Sending Message
Sending Message
Sending Message
Sending Message
Sending Message
Sending Message
Sending Message
Sending Message
Sending Message
Sending Message
Sending Message
Sending Message
Sending Message
Sending Message
Sending Message
Sending Message
Sending Message
Sending Message
Sending Message
Sending Message
Sending Message
Sending Message
Sending Message
Sending Message
Sending Message
Sending Message
Sending Message
Sending Message
Sending Message
Sending Message
Traceback (most recent call last):
  File "/usr/lib/python3/dist-packages/urllib3/connection.py", line 159, in _new_conn
    (self._dns_host, self.port), self.timeout, **extra_kw)
  File "/usr/lib/python3/dist-packages/urllib3/util/connection.py", line 80, in create_connection
    raise err
  File "/usr/lib/python3/dist-packages/urllib3/util/connection.py", line 70, in create_connection
    sock.connect(sa)
OSError: [Errno 113] No route to host

During handling of the above exception, another exception occurred:

Traceback (most recent call last):
  File "/usr/lib/python3/dist-packages/urllib3/connectionpool.py", line 600, in urlopen
    chunked=chunked)
  File "/usr/lib/python3/dist-packages/urllib3/connectionpool.py", line 343, in _make_request
    self._validate_conn(conn)
  File "/usr/lib/python3/dist-packages/urllib3/connectionpool.py", line 841, in _validate_conn
    conn.connect()
  File "/usr/lib/python3/dist-packages/urllib3/connection.py", line 301, in connect
    conn = self._new_conn()
  File "/usr/lib/python3/dist-packages/urllib3/connection.py", line 168, in _new_conn
    self, "Failed to establish a new connection: %s" % e)
urllib3.exceptions.NewConnectionError: <urllib3.connection.VerifiedHTTPSConnection object at 0x7f363ceb22e8>: Failed to establish a new connection: [Errno 113] No route to host

During handling of the above exception, another exception occurred:

Traceback (most recent call last):
  File "/usr/lib/python3/dist-packages/requests/adapters.py", line 449, in send
    timeout=timeout
  File "/usr/lib/python3/dist-packages/urllib3/connectionpool.py", line 638, in urlopen
    _stacktrace=sys.exc_info()[2])
  File "/usr/lib/python3/dist-packages/urllib3/util/retry.py", line 398, in increment
    raise MaxRetryError(_pool, url, error or ResponseError(cause))
urllib3.exceptions.MaxRetryError: HTTPSConnectionPool(host='ll.thespacedevs.com', port=443): Max retries exceeded with url: /2.0.0/launch/upcoming?mode=list (Caused by NewConnectionError('<urllib3.connection.VerifiedHTTPSConnection object at 0x7f363ceb22e8>: Failed to establish a new connection: [Errno 113] No route to host'))

During handling of the above exception, another exception occurred:

Traceback (most recent call last):
  File "print_launches.py", line 6, in <module>
    import get_launches
  File "/home/finn/STM32-Discord-Bot/get_launches.py", line 91, in <module>
    update_launches()
  File "/home/finn/STM32-Discord-Bot/get_launches.py", line 87, in update_launches
    launch_data = get_launch_json()
  File "/home/finn/STM32-Discord-Bot/get_launches.py", line 18, in get_launch_json
    requestData = requests.get('https://ll.thespacedevs.com/2.0.0/launch/upcoming?mode=list')
  File "/usr/lib/python3/dist-packages/requests/api.py", line 75, in get
    return request('get', url, params=params, **kwargs)
  File "/usr/lib/python3/dist-packages/requests/api.py", line 60, in request
    return session.request(method=method, url=url, **kwargs)
  File "/usr/lib/python3/dist-packages/requests/sessions.py", line 533, in request
    resp = self.send(prep, **send_kwargs)
  File "/usr/lib/python3/dist-packages/requests/sessions.py", line 646, in send
    r = adapter.send(request, **kwargs)
  File "/usr/lib/python3/dist-packages/requests/adapters.py", line 516, in send
    raise ConnectionError(e, request=request)
requests.exceptions.ConnectionError: HTTPSConnectionPool(host='ll.thespacedevs.com', port=443): Max retries exceeded with url: /2.0.0/launch/upcoming?mode=list (Caused by NewConnectionError('<urllib3.connection.VerifiedHTTPSConnection object at 0x7f363ceb22e8>: Failed to establish a new connection: [Errno 113] No route to host'))
Traceback (most recent call last):
  File "/usr/lib/python3/dist-packages/urllib3/connection.py", line 159, in _new_conn
    (self._dns_host, self.port), self.timeout, **extra_kw)
  File "/usr/lib/python3/dist-packages/urllib3/util/connection.py", line 80, in create_connection
    raise err
  File "/usr/lib/python3/dist-packages/urllib3/util/connection.py", line 70, in create_connection
    sock.connect(sa)
OSError: [Errno 113] No route to host

During handling of the above exception, another exception occurred:

Traceback (most recent call last):
  File "/usr/lib/python3/dist-packages/urllib3/connectionpool.py", line 600, in urlopen
    chunked=chunked)
  File "/usr/lib/python3/dist-packages/urllib3/connectionpool.py", line 343, in _make_request
    self._validate_conn(conn)
  File "/usr/lib/python3/dist-packages/urllib3/connectionpool.py", line 841, in _validate_conn
    conn.connect()
  File "/usr/lib/python3/dist-packages/urllib3/connection.py", line 301, in connect
    conn = self._new_conn()
  File "/usr/lib/python3/dist-packages/urllib3/connection.py", line 168, in _new_conn
    self, "Failed to establish a new connection: %s" % e)
urllib3.exceptions.NewConnectionError: <urllib3.connection.VerifiedHTTPSConnection object at 0x7f453ac39c18>: Failed to establish a new connection: [Errno 113] No route to host

During handling of the above exception, another exception occurred:

Traceback (most recent call last):
  File "/usr/lib/python3/dist-packages/requests/adapters.py", line 449, in send
    timeout=timeout
  File "/usr/lib/python3/dist-packages/urllib3/connectionpool.py", line 638, in urlopen
    _stacktrace=sys.exc_info()[2])
  File "/usr/lib/python3/dist-packages/urllib3/util/retry.py", line 398, in increment
    raise MaxRetryError(_pool, url, error or ResponseError(cause))
urllib3.exceptions.MaxRetryError: HTTPSConnectionPool(host='ll.thespacedevs.com', port=443): Max retries exceeded with url: /2.0.0/launch/upcoming?mode=list (Caused by NewConnectionError('<urllib3.connection.VerifiedHTTPSConnection object at 0x7f453ac39c18>: Failed to establish a new connection: [Errno 113] No route to host'))

During handling of the above exception, another exception occurred:

Traceback (most recent call last):
  File "print_launches.py", line 6, in <module>
    import get_launches
  File "/home/finn/STM32-Discord-Bot/get_launches.py", line 91, in <module>
    update_launches()
  File "/home/finn/STM32-Discord-Bot/get_launches.py", line 87, in update_launches
    launch_data = get_launch_json()
  File "/home/finn/STM32-Discord-Bot/get_launches.py", line 18, in get_launch_json
    requestData = requests.get('https://ll.thespacedevs.com/2.0.0/launch/upcoming?mode=list')
  File "/usr/lib/python3/dist-packages/requests/api.py", line 75, in get
    return request('get', url, params=params, **kwargs)
  File "/usr/lib/python3/dist-packages/requests/api.py", line 60, in request
    return session.request(method=method, url=url, **kwargs)
  File "/usr/lib/python3/dist-packages/requests/sessions.py", line 533, in request
    resp = self.send(prep, **send_kwargs)
  File "/usr/lib/python3/dist-packages/requests/sessions.py", line 646, in send
    r = adapter.send(request, **kwargs)
  File "/usr/lib/python3/dist-packages/requests/adapters.py", line 516, in send
    raise ConnectionError(e, request=request)
requests.exceptions.ConnectionError: HTTPSConnectionPool(host='ll.thespacedevs.com', port=443): Max retries exceeded with url: /2.0.0/launch/upcoming?mode=list (Caused by NewConnectionError('<urllib3.connection.VerifiedHTTPSConnection object at 0x7f453ac39c18>: Failed to establish a new connection: [Errno 113] No route to host'))
Traceback (most recent call last):
  File "/usr/lib/python3/dist-packages/urllib3/connectionpool.py", line 600, in urlopen
    chunked=chunked)
  File "/usr/lib/python3/dist-packages/urllib3/connectionpool.py", line 384, in _make_request
    six.raise_from(e, None)
  File "<string>", line 3, in raise_from
  File "/usr/lib/python3/dist-packages/urllib3/connectionpool.py", line 380, in _make_request
    httplib_response = conn.getresponse()
  File "/usr/lib/python3.7/http/client.py", line 1352, in getresponse
    response.begin()
  File "/usr/lib/python3.7/http/client.py", line 310, in begin
    version, status, reason = self._read_status()
  File "/usr/lib/python3.7/http/client.py", line 271, in _read_status
    line = str(self.fp.readline(_MAXLINE + 1), "iso-8859-1")
  File "/usr/lib/python3.7/socket.py", line 589, in readinto
    return self._sock.recv_into(b)
  File "/usr/lib/python3.7/ssl.py", line 1052, in recv_into
    return self.read(nbytes, buffer)
  File "/usr/lib/python3.7/ssl.py", line 911, in read
    return self._sslobj.read(len, buffer)
ConnectionResetError: [Errno 104] Connection reset by peer

During handling of the above exception, another exception occurred:

Traceback (most recent call last):
  File "/usr/lib/python3/dist-packages/requests/adapters.py", line 449, in send
    timeout=timeout
  File "/usr/lib/python3/dist-packages/urllib3/connectionpool.py", line 638, in urlopen
    _stacktrace=sys.exc_info()[2])
  File "/usr/lib/python3/dist-packages/urllib3/util/retry.py", line 367, in increment
    raise six.reraise(type(error), error, _stacktrace)
  File "/usr/lib/python3/dist-packages/six.py", line 692, in reraise
    raise value.with_traceback(tb)
  File "/usr/lib/python3/dist-packages/urllib3/connectionpool.py", line 600, in urlopen
    chunked=chunked)
  File "/usr/lib/python3/dist-packages/urllib3/connectionpool.py", line 384, in _make_request
    six.raise_from(e, None)
  File "<string>", line 3, in raise_from
  File "/usr/lib/python3/dist-packages/urllib3/connectionpool.py", line 380, in _make_request
    httplib_response = conn.getresponse()
  File "/usr/lib/python3.7/http/client.py", line 1352, in getresponse
    response.begin()
  File "/usr/lib/python3.7/http/client.py", line 310, in begin
    version, status, reason = self._read_status()
  File "/usr/lib/python3.7/http/client.py", line 271, in _read_status
    line = str(self.fp.readline(_MAXLINE + 1), "iso-8859-1")
  File "/usr/lib/python3.7/socket.py", line 589, in readinto
    return self._sock.recv_into(b)
  File "/usr/lib/python3.7/ssl.py", line 1052, in recv_into
    return self.read(nbytes, buffer)
  File "/usr/lib/python3.7/ssl.py", line 911, in read
    return self._sslobj.read(len, buffer)
urllib3.exceptions.ProtocolError: ('Connection aborted.', ConnectionResetError(104, 'Connection reset by peer'))

During handling of the above exception, another exception occurred:

Traceback (most recent call last):
  File "print_launches.py", line 6, in <module>
    import get_launches
  File "/home/finn/STM32-Discord-Bot/get_launches.py", line 91, in <module>
    update_launches()
  File "/home/finn/STM32-Discord-Bot/get_launches.py", line 87, in update_launches
    launch_data = get_launch_json()
  File "/home/finn/STM32-Discord-Bot/get_launches.py", line 18, in get_launch_json
    requestData = requests.get('https://ll.thespacedevs.com/2.0.0/launch/upcoming?mode=list')
  File "/usr/lib/python3/dist-packages/requests/api.py", line 75, in get
    return request('get', url, params=params, **kwargs)
  File "/usr/lib/python3/dist-packages/requests/api.py", line 60, in request
    return session.request(method=method, url=url, **kwargs)
  File "/usr/lib/python3/dist-packages/requests/sessions.py", line 533, in request
    resp = self.send(prep, **send_kwargs)
  File "/usr/lib/python3/dist-packages/requests/sessions.py", line 668, in send
    history = [resp for resp in gen] if allow_redirects else []
  File "/usr/lib/python3/dist-packages/requests/sessions.py", line 668, in <listcomp>
    history = [resp for resp in gen] if allow_redirects else []
  File "/usr/lib/python3/dist-packages/requests/sessions.py", line 247, in resolve_redirects
    **adapter_kwargs
  File "/usr/lib/python3/dist-packages/requests/sessions.py", line 646, in send
    r = adapter.send(request, **kwargs)
  File "/usr/lib/python3/dist-packages/requests/adapters.py", line 498, in send
    raise ConnectionError(err, request=request)
requests.exceptions.ConnectionError: ('Connection aborted.', ConnectionResetError(104, 'Connection reset by peer'))
Sending Message
Sending Message
Sending Message
Sending Message
Sending Message
Sending Message
Sending Message
Sending Message
Sending Message
Traceback (most recent call last):
  File "/usr/lib/python3/dist-packages/urllib3/connection.py", line 159, in _new_conn
    (self._dns_host, self.port), self.timeout, **extra_kw)
  File "/usr/lib/python3/dist-packages/urllib3/util/connection.py", line 57, in create_connection
    for res in socket.getaddrinfo(host, port, family, socket.SOCK_STREAM):
  File "/usr/lib/python3.7/socket.py", line 748, in getaddrinfo
    for res in _socket.getaddrinfo(host, port, family, type, proto, flags):
socket.gaierror: [Errno -3] Temporary failure in name resolution

During handling of the above exception, another exception occurred:

Traceback (most recent call last):
  File "/usr/lib/python3/dist-packages/urllib3/connectionpool.py", line 600, in urlopen
    chunked=chunked)
  File "/usr/lib/python3/dist-packages/urllib3/connectionpool.py", line 343, in _make_request
    self._validate_conn(conn)
  File "/usr/lib/python3/dist-packages/urllib3/connectionpool.py", line 841, in _validate_conn
    conn.connect()
  File "/usr/lib/python3/dist-packages/urllib3/connection.py", line 301, in connect
    conn = self._new_conn()
  File "/usr/lib/python3/dist-packages/urllib3/connection.py", line 168, in _new_conn
    self, "Failed to establish a new connection: %s" % e)
urllib3.exceptions.NewConnectionError: <urllib3.connection.VerifiedHTTPSConnection object at 0x7f7a402c01d0>: Failed to establish a new connection: [Errno -3] Temporary failure in name resolution

During handling of the above exception, another exception occurred:

Traceback (most recent call last):
  File "/usr/lib/python3/dist-packages/requests/adapters.py", line 449, in send
    timeout=timeout
  File "/usr/lib/python3/dist-packages/urllib3/connectionpool.py", line 638, in urlopen
    _stacktrace=sys.exc_info()[2])
  File "/usr/lib/python3/dist-packages/urllib3/util/retry.py", line 398, in increment
    raise MaxRetryError(_pool, url, error or ResponseError(cause))
urllib3.exceptions.MaxRetryError: HTTPSConnectionPool(host='ll.thespacedevs.com', port=443): Max retries exceeded with url: /2.0.0/launch/upcoming?mode=list (Caused by NewConnectionError('<urllib3.connection.VerifiedHTTPSConnection object at 0x7f7a402c01d0>: Failed to establish a new connection: [Errno -3] Temporary failure in name resolution'))

During handling of the above exception, another exception occurred:

Traceback (most recent call last):
  File "print_launches.py", line 6, in <module>
    import get_launches
  File "/home/finn/STM32-Discord-Bot/get_launches.py", line 91, in <module>
    update_launches()
  File "/home/finn/STM32-Discord-Bot/get_launches.py", line 87, in update_launches
    launch_data = get_launch_json()
  File "/home/finn/STM32-Discord-Bot/get_launches.py", line 18, in get_launch_json
    requestData = requests.get('https://ll.thespacedevs.com/2.0.0/launch/upcoming?mode=list')
  File "/usr/lib/python3/dist-packages/requests/api.py", line 75, in get
    return request('get', url, params=params, **kwargs)
  File "/usr/lib/python3/dist-packages/requests/api.py", line 60, in request
    return session.request(method=method, url=url, **kwargs)
  File "/usr/lib/python3/dist-packages/requests/sessions.py", line 533, in request
    resp = self.send(prep, **send_kwargs)
  File "/usr/lib/python3/dist-packages/requests/sessions.py", line 646, in send
    r = adapter.send(request, **kwargs)
  File "/usr/lib/python3/dist-packages/requests/adapters.py", line 516, in send
    raise ConnectionError(e, request=request)
requests.exceptions.ConnectionError: HTTPSConnectionPool(host='ll.thespacedevs.com', port=443): Max retries exceeded with url: /2.0.0/launch/upcoming?mode=list (Caused by NewConnectionError('<urllib3.connection.VerifiedHTTPSConnection object at 0x7f7a402c01d0>: Failed to establish a new connection: [Errno -3] Temporary failure in name resolution'))
Sending Message
Sending Message
Sending Message
Sending Message
Ignoring exception in on_ready
Traceback (most recent call last):
  File "/home/finn/.local/lib/python3.7/site-packages/discord/client.py", line 343, in _run_event
    await coro(*args, **kwargs)
  File "print_launches.py", line 23, in on_ready
    await channel.send(message)
  File "/home/finn/.local/lib/python3.7/site-packages/discord/abc.py", line 937, in send
    message_reference=reference)
  File "/home/finn/.local/lib/python3.7/site-packages/discord/http.py", line 247, in request
    raise HTTPException(r, data)
discord.errors.HTTPException: 504 Gateway Time-out (error code: 0): <!DOCTYPE html>
<!--[if lt IE 7]> <html class="no-js ie6 oldie" lang="en-US"> <![endif]-->
<!--[if IE 7]>    <html class="no-js ie7 oldie" lang="en-US"> <![endif]-->
<!--[if IE 8]>    <html class="no-js ie8 oldie" lang="en-US"> <![endif]-->
<!--[if gt IE 8]><!--> <html class="no-js" lang="en-US"> <!--<![endif]-->
<head>


<title>discord.com | 504: Gateway time-out</title>
<meta charset="UTF-8" />
<meta http-equiv="Content-Type" content="text/html; charset=UTF-8" />
<meta http-equiv="X-UA-Compatible" content="IE=Edge,chrome=1" />
<meta name="robots" content="noindex, nofollow" />
<meta name="viewport" content="width=device-width,initial-scale=1" />
<link rel="stylesheet" id="cf_styles-css" href="/cdn-cgi/styles/main.css" type="text/css" media="screen,projection" />


<script type="text/javascript">
(function(){if(document.addEventListener&&window.XMLHttpRequest&&JSON&&JSON.stringify){var e=function(a){var c=document.getElementById("error-feedback-survey"),d=document.getElementById("error-feedback-success"),b=new XMLHttpRequest;a={event:"feedback clicked",properties:{errorCode:504,helpful:a,version:1}};b.open("POST","https://sparrow.cloudflare.com/api/v1/event");b.setRequestHeader("Content-Type","application/json");b.setRequestHeader("Sparrow-Source-Key","c771f0e4b54944bebf4261d44bd79a1e");
b.send(JSON.stringify(a));c.classList.add("feedback-hidden");d.classList.remove("feedback-hidden")};document.addEventListener("DOMContentLoaded",function(){var a=document.getElementById("error-feedback"),c=document.getElementById("feedback-button-yes"),d=document.getElementById("feedback-button-no");"classList"in a&&(a.classList.remove("feedback-hidden"),c.addEventListener("click",function(){e(!0)}),d.addEventListener("click",function(){e(!1)}))})}})();
</script>

</head>
<body>
<div id="cf-wrapper">

    

    <div id="cf-error-details" class="p-0">
        <header class="mx-auto pt-10 lg:pt-6 lg:px-8 w-240 lg:w-full mb-8">
            <h1 class="inline-block sm:block sm:mb-2 font-light text-60 lg:text-4xl text-black-dark leading-tight mr-2">
              
              <span class="cf-error-type">Error</span>
              <span class="cf-error-code">504</span>
            </h1>
            <span class="inline-block sm:block font-mono text-15 lg:text-sm lg:leading-relaxed">Ray ID: 6e012fcb2f7790dc &bull;</span>
            <span class="inline-block sm:block font-mono text-15 lg:text-sm lg:leading-relaxed">2022-02-19 17:24:35 UTC</span>
            <h2 class="text-gray-600 leading-1.3 text-3xl font-light">Gateway time-out</h2>
        </header>
        
        <div class="my-8 bg-gradient-gray">
            <div class="w-240 lg:w-full mx-auto">
                <div class="clearfix md:px-8">
                  
<div id="cf-browser-status" class=" relative w-1/3 md:w-full py-15 md:p-0 md:py-8 md:text-left md:border-solid md:border-0 md:border-b md:border-gray-400 overflow-hidden float-left md:float-none text-center">
  <div class="relative mb-10 md:m-0">
    <span class="cf-icon-browser block md:hidden h-20 bg-center bg-no-repeat"></span>
    <span class="cf-icon-ok w-12 h-12 absolute left-1/2 md:left-auto md:right-0 md:top-0 -ml-6 -bottom-4"></span>
  </div>
  <span class="md:block w-full truncate">You</span>
  <h3 class="md:inline-block mt-3 md:mt-0 text-2xl text-gray-600 font-light leading-1.3">Browser</h3>
  <span class="leading-1.3 text-2xl text-green-success">Working</span>
</div>

<div id="cf-cloudflare-status" class=" relative w-1/3 md:w-full py-15 md:p-0 md:py-8 md:text-left md:border-solid md:border-0 md:border-b md:border-gray-400 overflow-hidden float-left md:float-none text-center">
  <div class="relative mb-10 md:m-0">
    <span class="cf-icon-cloud block md:hidden h-20 bg-center bg-no-repeat"></span>
    <span class="cf-icon-ok w-12 h-12 absolute left-1/2 md:left-auto md:right-0 md:top-0 -ml-6 -bottom-4"></span>
  </div>
  <span class="md:block w-full truncate">Frankfurt</span>
  <h3 class="md:inline-block mt-3 md:mt-0 text-2xl text-gray-600 font-light leading-1.3">Cloudflare</h3>
  <span class="leading-1.3 text-2xl text-green-success">Working</span>
</div>

<div id="cf-host-status" class="cf-error-source relative w-1/3 md:w-full py-15 md:p-0 md:py-8 md:text-left md:border-solid md:border-0 md:border-b md:border-gray-400 overflow-hidden float-left md:float-none text-center">
  <div class="relative mb-10 md:m-0">
    <span class="cf-icon-server block md:hidden h-20 bg-center bg-no-repeat"></span>
    <span class="cf-icon-error w-12 h-12 absolute left-1/2 md:left-auto md:right-0 md:top-0 -ml-6 -bottom-4"></span>
  </div>
  <span class="md:block w-full truncate">discord.com</span>
  <h3 class="md:inline-block mt-3 md:mt-0 text-2xl text-gray-600 font-light leading-1.3">Host</h3>
  <span class="leading-1.3 text-2xl text-red-error">Error</span>
</div>

                </div>
              
            </div>
        </div>

        <div class="w-240 lg:w-full mx-auto mb-8 lg:px-8">
            <div class="clearfix">
                <div class="w-1/2 md:w-full float-left pr-6 md:pb-10 md:pr-0 leading-relaxed">
                    <h2 class="text-3xl font-normal leading-1.3 mb-4">What happened?</h2>
                    <p>The web server reported a gateway time-out error.</p>
                </div>
              
                <div class="w-1/2 md:w-full float-left leading-relaxed">
                    <h2 class="text-3xl font-normal leading-1.3 mb-4">What can I do?</h2>
                    <p class="mb-6">Please try again in a few minutes.</p>
                </div>
            </div>
              
        </div>

        
        <div class="feedback-hidden py-8 text-center" id="error-feedback">
           <div id="error-feedback-survey">
              Was this page helpful?
              <button class="border border-solid bg-white cf-button cursor-pointer ml-4 px-4 py-2 rounded" id="feedback-button-yes" type="button">Yes</button>
              <button class="border border-solid bg-white cf-button cursor-pointer ml-4 px-4 py-2 rounded" id="feedback-button-no" type="button">No</button>
           </div>
           <div class="feedback-success feedback-hidden" id="error-feedback-success">
              Thank you for your feedback!
           </div>
        </div>
        

        <div class="cf-error-footer cf-wrapper w-240 lg:w-full py-10 sm:py-4 sm:px-8 mx-auto text-center sm:text-left border-solid border-0 border-t border-gray-300">
  <p class="text-13">
    <span class="cf-footer-item sm:block sm:mb-1">Cloudflare Ray ID: <strong class="font-semibold">6e012fcb2f7790dc</strong></span>
    <span class="cf-footer-separator sm:hidden">&bull;</span>
    <span class="cf-footer-item sm:block sm:mb-1"><span>Your IP</span>: 193.196.52.91</span>
    <span class="cf-footer-separator sm:hidden">&bull;</span>
    <span class="cf-footer-item sm:block sm:mb-1"><span>Performance &amp; security by</span> <a rel="noopener noreferrer" href="https://www.cloudflare.com/5xx-error-landing" id="brand_link" target="_blank">Cloudflare</a></span>
    
  </p>
</div><!-- /.error-footer -->


    </div>
</div>
</body>
</html>


Sending Message
Sending Message
Ignoring exception in on_ready
Traceback (most recent call last):
  File "/home/finn/.local/lib/python3.7/site-packages/discord/client.py", line 343, in _run_event
    await coro(*args, **kwargs)
  File "print_launches.py", line 23, in on_ready
    await channel.send(message)
  File "/home/finn/.local/lib/python3.7/site-packages/discord/abc.py", line 937, in send
    message_reference=reference)
  File "/home/finn/.local/lib/python3.7/site-packages/discord/http.py", line 247, in request
    raise HTTPException(r, data)
discord.errors.HTTPException: 504 Gateway Time-out (error code: 0): <!DOCTYPE html>
<!--[if lt IE 7]> <html class="no-js ie6 oldie" lang="en-US"> <![endif]-->
<!--[if IE 7]>    <html class="no-js ie7 oldie" lang="en-US"> <![endif]-->
<!--[if IE 8]>    <html class="no-js ie8 oldie" lang="en-US"> <![endif]-->
<!--[if gt IE 8]><!--> <html class="no-js" lang="en-US"> <!--<![endif]-->
<head>


<title>discord.com | 504: Gateway time-out</title>
<meta charset="UTF-8" />
<meta http-equiv="Content-Type" content="text/html; charset=UTF-8" />
<meta http-equiv="X-UA-Compatible" content="IE=Edge,chrome=1" />
<meta name="robots" content="noindex, nofollow" />
<meta name="viewport" content="width=device-width,initial-scale=1" />
<link rel="stylesheet" id="cf_styles-css" href="/cdn-cgi/styles/main.css" type="text/css" media="screen,projection" />


</head>
<body>
<div id="cf-wrapper">

    

    <div id="cf-error-details" class="p-0">
        <header class="mx-auto pt-10 lg:pt-6 lg:px-8 w-240 lg:w-full mb-8">
            <h1 class="inline-block sm:block sm:mb-2 font-light text-60 lg:text-4xl text-black-dark leading-tight mr-2">
              
              <span class="cf-error-type">Error</span>
              <span class="cf-error-code">504</span>
            </h1>
            <span class="inline-block sm:block font-mono text-15 lg:text-sm lg:leading-relaxed">Ray ID: 6d3540c1d91e916a &bull;</span>
            <span class="inline-block sm:block font-mono text-15 lg:text-sm lg:leading-relaxed">2022-01-25 23:24:34 UTC</span>
            <h2 class="text-gray-600 leading-1.3 text-3xl font-light">Gateway time-out</h2>
        </header>
        
        <div class="my-8 bg-gradient-gray">
            <div class="w-240 lg:w-full mx-auto">
                <div class="clearfix md:px-8">
                  
<div id="cf-browser-status" class=" relative w-1/3 md:w-full py-15 md:p-0 md:py-8 md:text-left md:border-solid md:border-0 md:border-b md:border-gray-400 overflow-hidden float-left md:float-none text-center">
  <div class="relative mb-10 md:m-0">
    <span class="cf-icon-browser block md:hidden h-20 bg-center bg-no-repeat"></span>
    <span class="cf-icon-ok w-12 h-12 absolute left-1/2 md:left-auto md:right-0 md:top-0 -ml-6 -bottom-4"></span>
  </div>
  <span class="md:block w-full truncate">You</span>
  <h3 class="md:inline-block mt-3 md:mt-0 text-2xl text-gray-600 font-light leading-1.3">Browser</h3>
  <span class="leading-1.3 text-2xl text-green-success">Working</span>
</div>

<div id="cf-cloudflare-status" class=" relative w-1/3 md:w-full py-15 md:p-0 md:py-8 md:text-left md:border-solid md:border-0 md:border-b md:border-gray-400 overflow-hidden float-left md:float-none text-center">
  <div class="relative mb-10 md:m-0">
    <span class="cf-icon-cloud block md:hidden h-20 bg-center bg-no-repeat"></span>
    <span class="cf-icon-ok w-12 h-12 absolute left-1/2 md:left-auto md:right-0 md:top-0 -ml-6 -bottom-4"></span>
  </div>
  <span class="md:block w-full truncate">Frankfurt</span>
  <h3 class="md:inline-block mt-3 md:mt-0 text-2xl text-gray-600 font-light leading-1.3">Cloudflare</h3>
  <span class="leading-1.3 text-2xl text-green-success">Working</span>
</div>

<div id="cf-host-status" class="cf-error-source relative w-1/3 md:w-full py-15 md:p-0 md:py-8 md:text-left md:border-solid md:border-0 md:border-b md:border-gray-400 overflow-hidden float-left md:float-none text-center">
  <div class="relative mb-10 md:m-0">
    <span class="cf-icon-server block md:hidden h-20 bg-center bg-no-repeat"></span>
    <span class="cf-icon-error w-12 h-12 absolute left-1/2 md:left-auto md:right-0 md:top-0 -ml-6 -bottom-4"></span>
  </div>
  <span class="md:block w-full truncate">discord.com</span>
  <h3 class="md:inline-block mt-3 md:mt-0 text-2xl text-gray-600 font-light leading-1.3">Host</h3>
  <span class="leading-1.3 text-2xl text-red-error">Error</span>
</div>

                </div>
              
            </div>
        </div>

        <div class="w-240 lg:w-full mx-auto mb-8 lg:px-8">
            <div class="clearfix">
                <div class="w-1/2 md:w-full float-left pr-6 md:pb-10 md:pr-0 leading-relaxed">
                    <h2 class="text-3xl font-normal leading-1.3 mb-4">What happened?</h2>
                    <p>The web server reported a gateway time-out error.</p>
                </div>
              
                <div class="w-1/2 md:w-full float-left leading-relaxed">
                    <h2 class="text-3xl font-normal leading-1.3 mb-4">What can I do?</h2>
                    <p class="mb-6">Please try again in a few minutes.</p>
                </div>
            </div>
              
        </div>

        <div class="cf-error-footer cf-wrapper w-240 lg:w-full py-10 sm:py-4 sm:px-8 mx-auto text-center sm:text-left border-solid border-0 border-t border-gray-300">
  <p class="text-13">
    <span class="cf-footer-item sm:block sm:mb-1">Cloudflare Ray ID: <strong class="font-semibold">6d3540c1d91e916a</strong></span>
    <span class="cf-footer-separator sm:hidden">&bull;</span>
    <span class="cf-footer-item sm:block sm:mb-1"><span>Your IP</span>: 193.196.52.91</span>
    <span class="cf-footer-separator sm:hidden">&bull;</span>
    <span class="cf-footer-item sm:block sm:mb-1"><span>Performance &amp; security by</span> <a rel="noopener noreferrer" href="https://www.cloudflare.com/5xx-error-landing" id="brand_link" target="_blank">Cloudflare</a></span>
    
  </p>
</div><!-- /.error-footer -->


    </div>
</div>
</body>
</html>


Sending Message
Sending Message
Sending Message
Sending Message
Sending Message
Sending Message
Sending Message
Sending Message
Sending Message
Sending Message
Sending Message
Sending Message
Sending Message
Sending Message
Sending Message
Sending Message
Sending Message
Sending Message
Sending Message
Traceback (most recent call last):
  File "/usr/lib/python3/dist-packages/urllib3/connection.py", line 159, in _new_conn
    (self._dns_host, self.port), self.timeout, **extra_kw)
  File "/usr/lib/python3/dist-packages/urllib3/util/connection.py", line 57, in create_connection
    for res in socket.getaddrinfo(host, port, family, socket.SOCK_STREAM):
  File "/usr/lib/python3.7/socket.py", line 748, in getaddrinfo
    for res in _socket.getaddrinfo(host, port, family, type, proto, flags):
socket.gaierror: [Errno -3] Temporary failure in name resolution

During handling of the above exception, another exception occurred:

Traceback (most recent call last):
  File "/usr/lib/python3/dist-packages/urllib3/connectionpool.py", line 600, in urlopen
    chunked=chunked)
  File "/usr/lib/python3/dist-packages/urllib3/connectionpool.py", line 343, in _make_request
    self._validate_conn(conn)
  File "/usr/lib/python3/dist-packages/urllib3/connectionpool.py", line 841, in _validate_conn
    conn.connect()
  File "/usr/lib/python3/dist-packages/urllib3/connection.py", line 301, in connect
    conn = self._new_conn()
  File "/usr/lib/python3/dist-packages/urllib3/connection.py", line 168, in _new_conn
    self, "Failed to establish a new connection: %s" % e)
urllib3.exceptions.NewConnectionError: <urllib3.connection.VerifiedHTTPSConnection object at 0x7ff412ad42b0>: Failed to establish a new connection: [Errno -3] Temporary failure in name resolution

During handling of the above exception, another exception occurred:

Traceback (most recent call last):
  File "/usr/lib/python3/dist-packages/requests/adapters.py", line 449, in send
    timeout=timeout
  File "/usr/lib/python3/dist-packages/urllib3/connectionpool.py", line 638, in urlopen
    _stacktrace=sys.exc_info()[2])
  File "/usr/lib/python3/dist-packages/urllib3/util/retry.py", line 398, in increment
    raise MaxRetryError(_pool, url, error or ResponseError(cause))
urllib3.exceptions.MaxRetryError: HTTPSConnectionPool(host='ll.thespacedevs.com', port=443): Max retries exceeded with url: /2.0.0/launch/upcoming?mode=list (Caused by NewConnectionError('<urllib3.connection.VerifiedHTTPSConnection object at 0x7ff412ad42b0>: Failed to establish a new connection: [Errno -3] Temporary failure in name resolution'))

During handling of the above exception, another exception occurred:

Traceback (most recent call last):
  File "print_launches.py", line 6, in <module>
    import get_launches
  File "/home/finn/STM32-Discord-Bot/get_launches.py", line 91, in <module>
    update_launches()
  File "/home/finn/STM32-Discord-Bot/get_launches.py", line 87, in update_launches
    launch_data = get_launch_json()
  File "/home/finn/STM32-Discord-Bot/get_launches.py", line 18, in get_launch_json
    requestData = requests.get('https://ll.thespacedevs.com/2.0.0/launch/upcoming?mode=list')
  File "/usr/lib/python3/dist-packages/requests/api.py", line 75, in get
    return request('get', url, params=params, **kwargs)
  File "/usr/lib/python3/dist-packages/requests/api.py", line 60, in request
    return session.request(method=method, url=url, **kwargs)
  File "/usr/lib/python3/dist-packages/requests/sessions.py", line 533, in request
    resp = self.send(prep, **send_kwargs)
  File "/usr/lib/python3/dist-packages/requests/sessions.py", line 646, in send
    r = adapter.send(request, **kwargs)
  File "/usr/lib/python3/dist-packages/requests/adapters.py", line 516, in send
    raise ConnectionError(e, request=request)
requests.exceptions.ConnectionError: HTTPSConnectionPool(host='ll.thespacedevs.com', port=443): Max retries exceeded with url: /2.0.0/launch/upcoming?mode=list (Caused by NewConnectionError('<urllib3.connection.VerifiedHTTPSConnection object at 0x7ff412ad42b0>: Failed to establish a new connection: [Errno -3] Temporary failure in name resolution'))
Traceback (most recent call last):
  File "/usr/lib/python3/dist-packages/urllib3/connection.py", line 159, in _new_conn
    (self._dns_host, self.port), self.timeout, **extra_kw)
  File "/usr/lib/python3/dist-packages/urllib3/util/connection.py", line 57, in create_connection
    for res in socket.getaddrinfo(host, port, family, socket.SOCK_STREAM):
  File "/usr/lib/python3.7/socket.py", line 748, in getaddrinfo
    for res in _socket.getaddrinfo(host, port, family, type, proto, flags):
socket.gaierror: [Errno -3] Temporary failure in name resolution

During handling of the above exception, another exception occurred:

Traceback (most recent call last):
  File "/usr/lib/python3/dist-packages/urllib3/connectionpool.py", line 600, in urlopen
    chunked=chunked)
  File "/usr/lib/python3/dist-packages/urllib3/connectionpool.py", line 343, in _make_request
    self._validate_conn(conn)
  File "/usr/lib/python3/dist-packages/urllib3/connectionpool.py", line 841, in _validate_conn
    conn.connect()
  File "/usr/lib/python3/dist-packages/urllib3/connection.py", line 301, in connect
    conn = self._new_conn()
  File "/usr/lib/python3/dist-packages/urllib3/connection.py", line 168, in _new_conn
    self, "Failed to establish a new connection: %s" % e)
urllib3.exceptions.NewConnectionError: <urllib3.connection.VerifiedHTTPSConnection object at 0x7f8fc19bf358>: Failed to establish a new connection: [Errno -3] Temporary failure in name resolution

During handling of the above exception, another exception occurred:

Traceback (most recent call last):
  File "/usr/lib/python3/dist-packages/requests/adapters.py", line 449, in send
    timeout=timeout
  File "/usr/lib/python3/dist-packages/urllib3/connectionpool.py", line 638, in urlopen
    _stacktrace=sys.exc_info()[2])
  File "/usr/lib/python3/dist-packages/urllib3/util/retry.py", line 398, in increment
    raise MaxRetryError(_pool, url, error or ResponseError(cause))
urllib3.exceptions.MaxRetryError: HTTPSConnectionPool(host='ll.thespacedevs.com', port=443): Max retries exceeded with url: /2.0.0/launch/upcoming?mode=list (Caused by NewConnectionError('<urllib3.connection.VerifiedHTTPSConnection object at 0x7f8fc19bf358>: Failed to establish a new connection: [Errno -3] Temporary failure in name resolution'))

During handling of the above exception, another exception occurred:

Traceback (most recent call last):
  File "print_launches.py", line 6, in <module>
    import get_launches
  File "/home/finn/STM32-Discord-Bot/get_launches.py", line 91, in <module>
    update_launches()
  File "/home/finn/STM32-Discord-Bot/get_launches.py", line 87, in update_launches
    launch_data = get_launch_json()
  File "/home/finn/STM32-Discord-Bot/get_launches.py", line 18, in get_launch_json
    requestData = requests.get('https://ll.thespacedevs.com/2.0.0/launch/upcoming?mode=list')
  File "/usr/lib/python3/dist-packages/requests/api.py", line 75, in get
    return request('get', url, params=params, **kwargs)
  File "/usr/lib/python3/dist-packages/requests/api.py", line 60, in request
    return session.request(method=method, url=url, **kwargs)
  File "/usr/lib/python3/dist-packages/requests/sessions.py", line 533, in request
    resp = self.send(prep, **send_kwargs)
  File "/usr/lib/python3/dist-packages/requests/sessions.py", line 646, in send
    r = adapter.send(request, **kwargs)
  File "/usr/lib/python3/dist-packages/requests/adapters.py", line 516, in send
    raise ConnectionError(e, request=request)
requests.exceptions.ConnectionError: HTTPSConnectionPool(host='ll.thespacedevs.com', port=443): Max retries exceeded with url: /2.0.0/launch/upcoming?mode=list (Caused by NewConnectionError('<urllib3.connection.VerifiedHTTPSConnection object at 0x7f8fc19bf358>: Failed to establish a new connection: [Errno -3] Temporary failure in name resolution'))
Traceback (most recent call last):
  File "/usr/lib/python3/dist-packages/urllib3/connection.py", line 159, in _new_conn
    (self._dns_host, self.port), self.timeout, **extra_kw)
  File "/usr/lib/python3/dist-packages/urllib3/util/connection.py", line 57, in create_connection
    for res in socket.getaddrinfo(host, port, family, socket.SOCK_STREAM):
  File "/usr/lib/python3.7/socket.py", line 748, in getaddrinfo
    for res in _socket.getaddrinfo(host, port, family, type, proto, flags):
socket.gaierror: [Errno -3] Temporary failure in name resolution

During handling of the above exception, another exception occurred:

Traceback (most recent call last):
  File "/usr/lib/python3/dist-packages/urllib3/connectionpool.py", line 600, in urlopen
    chunked=chunked)
  File "/usr/lib/python3/dist-packages/urllib3/connectionpool.py", line 343, in _make_request
    self._validate_conn(conn)
  File "/usr/lib/python3/dist-packages/urllib3/connectionpool.py", line 841, in _validate_conn
    conn.connect()
  File "/usr/lib/python3/dist-packages/urllib3/connection.py", line 301, in connect
    conn = self._new_conn()
  File "/usr/lib/python3/dist-packages/urllib3/connection.py", line 168, in _new_conn
    self, "Failed to establish a new connection: %s" % e)
urllib3.exceptions.NewConnectionError: <urllib3.connection.VerifiedHTTPSConnection object at 0x7f11c9c37278>: Failed to establish a new connection: [Errno -3] Temporary failure in name resolution

During handling of the above exception, another exception occurred:

Traceback (most recent call last):
  File "/usr/lib/python3/dist-packages/requests/adapters.py", line 449, in send
    timeout=timeout
  File "/usr/lib/python3/dist-packages/urllib3/connectionpool.py", line 638, in urlopen
    _stacktrace=sys.exc_info()[2])
  File "/usr/lib/python3/dist-packages/urllib3/util/retry.py", line 398, in increment
    raise MaxRetryError(_pool, url, error or ResponseError(cause))
urllib3.exceptions.MaxRetryError: HTTPSConnectionPool(host='ll.thespacedevs.com', port=443): Max retries exceeded with url: /2.0.0/launch/upcoming?mode=list (Caused by NewConnectionError('<urllib3.connection.VerifiedHTTPSConnection object at 0x7f11c9c37278>: Failed to establish a new connection: [Errno -3] Temporary failure in name resolution'))

During handling of the above exception, another exception occurred:

Traceback (most recent call last):
  File "print_launches.py", line 6, in <module>
    import get_launches
  File "/home/finn/STM32-Discord-Bot/get_launches.py", line 91, in <module>
    update_launches()
  File "/home/finn/STM32-Discord-Bot/get_launches.py", line 87, in update_launches
    launch_data = get_launch_json()
  File "/home/finn/STM32-Discord-Bot/get_launches.py", line 18, in get_launch_json
    requestData = requests.get('https://ll.thespacedevs.com/2.0.0/launch/upcoming?mode=list')
  File "/usr/lib/python3/dist-packages/requests/api.py", line 75, in get
    return request('get', url, params=params, **kwargs)
  File "/usr/lib/python3/dist-packages/requests/api.py", line 60, in request
    return session.request(method=method, url=url, **kwargs)
  File "/usr/lib/python3/dist-packages/requests/sessions.py", line 533, in request
    resp = self.send(prep, **send_kwargs)
  File "/usr/lib/python3/dist-packages/requests/sessions.py", line 646, in send
    r = adapter.send(request, **kwargs)
  File "/usr/lib/python3/dist-packages/requests/adapters.py", line 516, in send
    raise ConnectionError(e, request=request)
requests.exceptions.ConnectionError: HTTPSConnectionPool(host='ll.thespacedevs.com', port=443): Max retries exceeded with url: /2.0.0/launch/upcoming?mode=list (Caused by NewConnectionError('<urllib3.connection.VerifiedHTTPSConnection object at 0x7f11c9c37278>: Failed to establish a new connection: [Errno -3] Temporary failure in name resolution'))
Sending Message
Sending Message
Sending Message
Sending Message
Sending Message
Sending Message
Sending Message
Sending Message
Sending Message
Sending Message
Sending Message
Sending Message
Sending Message
Sending Message
Traceback (most recent call last):
  File "/usr/lib/python3/dist-packages/urllib3/connection.py", line 159, in _new_conn
    (self._dns_host, self.port), self.timeout, **extra_kw)
  File "/usr/lib/python3/dist-packages/urllib3/util/connection.py", line 57, in create_connection
    for res in socket.getaddrinfo(host, port, family, socket.SOCK_STREAM):
  File "/usr/lib/python3.7/socket.py", line 748, in getaddrinfo
    for res in _socket.getaddrinfo(host, port, family, type, proto, flags):
socket.gaierror: [Errno -3] Temporary failure in name resolution

During handling of the above exception, another exception occurred:

Traceback (most recent call last):
  File "/usr/lib/python3/dist-packages/urllib3/connectionpool.py", line 600, in urlopen
    chunked=chunked)
  File "/usr/lib/python3/dist-packages/urllib3/connectionpool.py", line 343, in _make_request
    self._validate_conn(conn)
  File "/usr/lib/python3/dist-packages/urllib3/connectionpool.py", line 841, in _validate_conn
    conn.connect()
  File "/usr/lib/python3/dist-packages/urllib3/connection.py", line 301, in connect
    conn = self._new_conn()
  File "/usr/lib/python3/dist-packages/urllib3/connection.py", line 168, in _new_conn
    self, "Failed to establish a new connection: %s" % e)
urllib3.exceptions.NewConnectionError: <urllib3.connection.VerifiedHTTPSConnection object at 0x7f784e980d30>: Failed to establish a new connection: [Errno -3] Temporary failure in name resolution

During handling of the above exception, another exception occurred:

Traceback (most recent call last):
  File "/usr/lib/python3/dist-packages/requests/adapters.py", line 449, in send
    timeout=timeout
  File "/usr/lib/python3/dist-packages/urllib3/connectionpool.py", line 638, in urlopen
    _stacktrace=sys.exc_info()[2])
  File "/usr/lib/python3/dist-packages/urllib3/util/retry.py", line 398, in increment
    raise MaxRetryError(_pool, url, error or ResponseError(cause))
urllib3.exceptions.MaxRetryError: HTTPSConnectionPool(host='ll.thespacedevs.com', port=443): Max retries exceeded with url: /2.0.0/launch/upcoming?mode=list (Caused by NewConnectionError('<urllib3.connection.VerifiedHTTPSConnection object at 0x7f784e980d30>: Failed to establish a new connection: [Errno -3] Temporary failure in name resolution'))

During handling of the above exception, another exception occurred:

Traceback (most recent call last):
  File "print_launches.py", line 6, in <module>
    import get_launches
  File "/home/finn/STM32-Discord-Bot/get_launches.py", line 91, in <module>
    update_launches()
  File "/home/finn/STM32-Discord-Bot/get_launches.py", line 87, in update_launches
    launch_data = get_launch_json()
  File "/home/finn/STM32-Discord-Bot/get_launches.py", line 18, in get_launch_json
    requestData = requests.get('https://ll.thespacedevs.com/2.0.0/launch/upcoming?mode=list')
  File "/usr/lib/python3/dist-packages/requests/api.py", line 75, in get
    return request('get', url, params=params, **kwargs)
  File "/usr/lib/python3/dist-packages/requests/api.py", line 60, in request
    return session.request(method=method, url=url, **kwargs)
  File "/usr/lib/python3/dist-packages/requests/sessions.py", line 533, in request
    resp = self.send(prep, **send_kwargs)
  File "/usr/lib/python3/dist-packages/requests/sessions.py", line 646, in send
    r = adapter.send(request, **kwargs)
  File "/usr/lib/python3/dist-packages/requests/adapters.py", line 516, in send
    raise ConnectionError(e, request=request)
requests.exceptions.ConnectionError: HTTPSConnectionPool(host='ll.thespacedevs.com', port=443): Max retries exceeded with url: /2.0.0/launch/upcoming?mode=list (Caused by NewConnectionError('<urllib3.connection.VerifiedHTTPSConnection object at 0x7f784e980d30>: Failed to establish a new connection: [Errno -3] Temporary failure in name resolution'))
Sending Message
Sending Message
Sending Message
Traceback (most recent call last):
  File "/usr/lib/python3/dist-packages/urllib3/connection.py", line 159, in _new_conn
    (self._dns_host, self.port), self.timeout, **extra_kw)
  File "/usr/lib/python3/dist-packages/urllib3/util/connection.py", line 57, in create_connection
    for res in socket.getaddrinfo(host, port, family, socket.SOCK_STREAM):
  File "/usr/lib/python3.7/socket.py", line 748, in getaddrinfo
    for res in _socket.getaddrinfo(host, port, family, type, proto, flags):
socket.gaierror: [Errno -3] Temporary failure in name resolution

During handling of the above exception, another exception occurred:

Traceback (most recent call last):
  File "/usr/lib/python3/dist-packages/urllib3/connectionpool.py", line 600, in urlopen
    chunked=chunked)
  File "/usr/lib/python3/dist-packages/urllib3/connectionpool.py", line 343, in _make_request
    self._validate_conn(conn)
  File "/usr/lib/python3/dist-packages/urllib3/connectionpool.py", line 841, in _validate_conn
    conn.connect()
  File "/usr/lib/python3/dist-packages/urllib3/connection.py", line 301, in connect
    conn = self._new_conn()
  File "/usr/lib/python3/dist-packages/urllib3/connection.py", line 168, in _new_conn
    self, "Failed to establish a new connection: %s" % e)
urllib3.exceptions.NewConnectionError: <urllib3.connection.VerifiedHTTPSConnection object at 0x7efdf4ccc358>: Failed to establish a new connection: [Errno -3] Temporary failure in name resolution

During handling of the above exception, another exception occurred:

Traceback (most recent call last):
  File "/usr/lib/python3/dist-packages/requests/adapters.py", line 449, in send
    timeout=timeout
  File "/usr/lib/python3/dist-packages/urllib3/connectionpool.py", line 638, in urlopen
    _stacktrace=sys.exc_info()[2])
  File "/usr/lib/python3/dist-packages/urllib3/util/retry.py", line 398, in increment
    raise MaxRetryError(_pool, url, error or ResponseError(cause))
urllib3.exceptions.MaxRetryError: HTTPSConnectionPool(host='ll.thespacedevs.com', port=443): Max retries exceeded with url: /2.0.0/launch/upcoming?mode=list (Caused by NewConnectionError('<urllib3.connection.VerifiedHTTPSConnection object at 0x7efdf4ccc358>: Failed to establish a new connection: [Errno -3] Temporary failure in name resolution'))

During handling of the above exception, another exception occurred:

Traceback (most recent call last):
  File "print_launches.py", line 6, in <module>
    import get_launches
  File "/home/finn/STM32-Discord-Bot/get_launches.py", line 91, in <module>
    update_launches()
  File "/home/finn/STM32-Discord-Bot/get_launches.py", line 87, in update_launches
    launch_data = get_launch_json()
  File "/home/finn/STM32-Discord-Bot/get_launches.py", line 18, in get_launch_json
    requestData = requests.get('https://ll.thespacedevs.com/2.0.0/launch/upcoming?mode=list')
  File "/usr/lib/python3/dist-packages/requests/api.py", line 75, in get
    return request('get', url, params=params, **kwargs)
  File "/usr/lib/python3/dist-packages/requests/api.py", line 60, in request
    return session.request(method=method, url=url, **kwargs)
  File "/usr/lib/python3/dist-packages/requests/sessions.py", line 533, in request
    resp = self.send(prep, **send_kwargs)
  File "/usr/lib/python3/dist-packages/requests/sessions.py", line 646, in send
    r = adapter.send(request, **kwargs)
  File "/usr/lib/python3/dist-packages/requests/adapters.py", line 516, in send
    raise ConnectionError(e, request=request)
requests.exceptions.ConnectionError: HTTPSConnectionPool(host='ll.thespacedevs.com', port=443): Max retries exceeded with url: /2.0.0/launch/upcoming?mode=list (Caused by NewConnectionError('<urllib3.connection.VerifiedHTTPSConnection object at 0x7efdf4ccc358>: Failed to establish a new connection: [Errno -3] Temporary failure in name resolution'))
Sending Message
Sending Message
Sending Message
Sending Message
Sending Message
Sending Message
Sending Message
Sending Message
Sending Message
Traceback (most recent call last):
  File "print_launches.py", line 123, in <module>
    client.run(TOKEN)
  File "/home/finn/.local/lib/python3.7/site-packages/discord/client.py", line 718, in run
    return future.result()
  File "/home/finn/.local/lib/python3.7/site-packages/discord/client.py", line 697, in runner
    await self.start(*args, **kwargs)
  File "/home/finn/.local/lib/python3.7/site-packages/discord/client.py", line 660, in start
    await self.login(*args, bot=bot)
  File "/home/finn/.local/lib/python3.7/site-packages/discord/client.py", line 509, in login
    await self.http.static_login(token.strip(), bot=bot)
  File "/home/finn/.local/lib/python3.7/site-packages/discord/http.py", line 293, in static_login
    data = await self.request(Route('GET', '/users/@me'))
  File "/home/finn/.local/lib/python3.7/site-packages/discord/http.py", line 258, in request
    raise DiscordServerError(r, data)
discord.errors.DiscordServerError: 500 Internal Server Error (error code: 0): <html>
<head><title>500 Internal Server Error</title><script async src='/cdn-cgi/bm/cv/669835187/api.js'></script></head>
<body bgcolor="white">
<center><h1>500 Internal Server Error</h1></center>
<hr><center>nginx</center>
<script type="text/javascript">(function(){window['__CF$cv$params']={r:'71eac7e23ea3906d',m:'REcgnW.fjRQGi3yubxQHAuZkDURCnd41HRIhitDRztU-1655793920-0-AZvFK5NpuZvaw3Qs9pyipP9zdGgP0JStYXcoWN11jdD+dNCeWM1CKc325hQrjMgOL72WCZ/FkB2zfOiD/VOhz0w7iosEEmoOvej/NE++q1yQk8NKbiXRctb7eqebVdSBvq5DWegSqpaIC4HBayq/NBU=',s:[0x0ed81bc5a3,0xa90f70ab4f],}})();</script></body>
</html>

Sending Message
Sending Message
Sending Message
Sending Message
Sending Message
Sending Message
Sending Message
Traceback (most recent call last):
  File "/usr/lib/python3/dist-packages/urllib3/connectionpool.py", line 600, in urlopen
    chunked=chunked)
  File "/usr/lib/python3/dist-packages/urllib3/connectionpool.py", line 343, in _make_request
    self._validate_conn(conn)
  File "/usr/lib/python3/dist-packages/urllib3/connectionpool.py", line 841, in _validate_conn
    conn.connect()
  File "/usr/lib/python3/dist-packages/urllib3/connection.py", line 344, in connect
    ssl_context=context)
  File "/usr/lib/python3/dist-packages/urllib3/util/ssl_.py", line 344, in ssl_wrap_socket
    return context.wrap_socket(sock, server_hostname=server_hostname)
  File "/usr/lib/python3.7/ssl.py", line 412, in wrap_socket
    session=session
  File "/usr/lib/python3.7/ssl.py", line 853, in _create
    self.do_handshake()
  File "/usr/lib/python3.7/ssl.py", line 1117, in do_handshake
    self._sslobj.do_handshake()
ssl.SSLError: [SSL: SSLV3_ALERT_HANDSHAKE_FAILURE] sslv3 alert handshake failure (_ssl.c:1056)

During handling of the above exception, another exception occurred:

Traceback (most recent call last):
  File "/usr/lib/python3/dist-packages/requests/adapters.py", line 449, in send
    timeout=timeout
  File "/usr/lib/python3/dist-packages/urllib3/connectionpool.py", line 638, in urlopen
    _stacktrace=sys.exc_info()[2])
  File "/usr/lib/python3/dist-packages/urllib3/util/retry.py", line 398, in increment
    raise MaxRetryError(_pool, url, error or ResponseError(cause))
urllib3.exceptions.MaxRetryError: HTTPSConnectionPool(host='ll.thespacedevs.com', port=443): Max retries exceeded with url: /2.0.0/launch/upcoming?mode=list (Caused by SSLError(SSLError(1, '[SSL: SSLV3_ALERT_HANDSHAKE_FAILURE] sslv3 alert handshake failure (_ssl.c:1056)')))

During handling of the above exception, another exception occurred:

Traceback (most recent call last):
  File "print_launches.py", line 6, in <module>
    import get_launches
  File "/home/finn/STM32-Discord-Bot/get_launches.py", line 91, in <module>
    update_launches()
  File "/home/finn/STM32-Discord-Bot/get_launches.py", line 87, in update_launches
    launch_data = get_launch_json()
  File "/home/finn/STM32-Discord-Bot/get_launches.py", line 18, in get_launch_json
    requestData = requests.get('https://ll.thespacedevs.com/2.0.0/launch/upcoming?mode=list')
  File "/usr/lib/python3/dist-packages/requests/api.py", line 75, in get
    return request('get', url, params=params, **kwargs)
  File "/usr/lib/python3/dist-packages/requests/api.py", line 60, in request
    return session.request(method=method, url=url, **kwargs)
  File "/usr/lib/python3/dist-packages/requests/sessions.py", line 533, in request
    resp = self.send(prep, **send_kwargs)
  File "/usr/lib/python3/dist-packages/requests/sessions.py", line 646, in send
    r = adapter.send(request, **kwargs)
  File "/usr/lib/python3/dist-packages/requests/adapters.py", line 514, in send
    raise SSLError(e, request=request)
requests.exceptions.SSLError: HTTPSConnectionPool(host='ll.thespacedevs.com', port=443): Max retries exceeded with url: /2.0.0/launch/upcoming?mode=list (Caused by SSLError(SSLError(1, '[SSL: SSLV3_ALERT_HANDSHAKE_FAILURE] sslv3 alert handshake failure (_ssl.c:1056)')))
Sending Message
Sending Message
Sending Message
Sending Message
Sending Message
Sending Message
Sending Message
Sending Message
Sending Message
Sending Message
Sending Message
Sending Message
Sending Message
Traceback (most recent call last):
  File "/usr/lib/python3/dist-packages/urllib3/connectionpool.py", line 600, in urlopen
    chunked=chunked)
  File "/usr/lib/python3/dist-packages/urllib3/connectionpool.py", line 343, in _make_request
    self._validate_conn(conn)
  File "/usr/lib/python3/dist-packages/urllib3/connectionpool.py", line 841, in _validate_conn
    conn.connect()
  File "/usr/lib/python3/dist-packages/urllib3/connection.py", line 344, in connect
    ssl_context=context)
  File "/usr/lib/python3/dist-packages/urllib3/util/ssl_.py", line 344, in ssl_wrap_socket
    return context.wrap_socket(sock, server_hostname=server_hostname)
  File "/usr/lib/python3.7/ssl.py", line 412, in wrap_socket
    session=session
  File "/usr/lib/python3.7/ssl.py", line 853, in _create
    self.do_handshake()
  File "/usr/lib/python3.7/ssl.py", line 1117, in do_handshake
    self._sslobj.do_handshake()
ssl.SSLError: [SSL: SSLV3_ALERT_HANDSHAKE_FAILURE] sslv3 alert handshake failure (_ssl.c:1056)

During handling of the above exception, another exception occurred:

Traceback (most recent call last):
  File "/usr/lib/python3/dist-packages/requests/adapters.py", line 449, in send
    timeout=timeout
  File "/usr/lib/python3/dist-packages/urllib3/connectionpool.py", line 638, in urlopen
    _stacktrace=sys.exc_info()[2])
  File "/usr/lib/python3/dist-packages/urllib3/util/retry.py", line 398, in increment
    raise MaxRetryError(_pool, url, error or ResponseError(cause))
urllib3.exceptions.MaxRetryError: HTTPSConnectionPool(host='ll.thespacedevs.com', port=443): Max retries exceeded with url: /2.0.0/launch/upcoming?mode=list (Caused by SSLError(SSLError(1, '[SSL: SSLV3_ALERT_HANDSHAKE_FAILURE] sslv3 alert handshake failure (_ssl.c:1056)')))

During handling of the above exception, another exception occurred:

Traceback (most recent call last):
  File "print_launches.py", line 6, in <module>
    import get_launches
  File "/home/finn/STM32-Discord-Bot/get_launches.py", line 91, in <module>
    update_launches()
  File "/home/finn/STM32-Discord-Bot/get_launches.py", line 87, in update_launches
    launch_data = get_launch_json()
  File "/home/finn/STM32-Discord-Bot/get_launches.py", line 18, in get_launch_json
    requestData = requests.get('https://ll.thespacedevs.com/2.0.0/launch/upcoming?mode=list')
  File "/usr/lib/python3/dist-packages/requests/api.py", line 75, in get
    return request('get', url, params=params, **kwargs)
  File "/usr/lib/python3/dist-packages/requests/api.py", line 60, in request
    return session.request(method=method, url=url, **kwargs)
  File "/usr/lib/python3/dist-packages/requests/sessions.py", line 533, in request
    resp = self.send(prep, **send_kwargs)
  File "/usr/lib/python3/dist-packages/requests/sessions.py", line 646, in send
    r = adapter.send(request, **kwargs)
  File "/usr/lib/python3/dist-packages/requests/adapters.py", line 514, in send
    raise SSLError(e, request=request)
requests.exceptions.SSLError: HTTPSConnectionPool(host='ll.thespacedevs.com', port=443): Max retries exceeded with url: /2.0.0/launch/upcoming?mode=list (Caused by SSLError(SSLError(1, '[SSL: SSLV3_ALERT_HANDSHAKE_FAILURE] sslv3 alert handshake failure (_ssl.c:1056)')))
Sending Message
Sending Message
Sending Message
Sending Message
Sending Message
Traceback (most recent call last):
  File "/usr/lib/python3/dist-packages/urllib3/connectionpool.py", line 600, in urlopen
    chunked=chunked)
  File "/usr/lib/python3/dist-packages/urllib3/connectionpool.py", line 343, in _make_request
    self._validate_conn(conn)
  File "/usr/lib/python3/dist-packages/urllib3/connectionpool.py", line 841, in _validate_conn
    conn.connect()
  File "/usr/lib/python3/dist-packages/urllib3/connection.py", line 344, in connect
    ssl_context=context)
  File "/usr/lib/python3/dist-packages/urllib3/util/ssl_.py", line 344, in ssl_wrap_socket
    return context.wrap_socket(sock, server_hostname=server_hostname)
  File "/usr/lib/python3.7/ssl.py", line 412, in wrap_socket
    session=session
  File "/usr/lib/python3.7/ssl.py", line 853, in _create
    self.do_handshake()
  File "/usr/lib/python3.7/ssl.py", line 1117, in do_handshake
    self._sslobj.do_handshake()
ssl.SSLError: [SSL: SSLV3_ALERT_HANDSHAKE_FAILURE] sslv3 alert handshake failure (_ssl.c:1056)

During handling of the above exception, another exception occurred:

Traceback (most recent call last):
  File "/usr/lib/python3/dist-packages/requests/adapters.py", line 449, in send
    timeout=timeout
  File "/usr/lib/python3/dist-packages/urllib3/connectionpool.py", line 638, in urlopen
    _stacktrace=sys.exc_info()[2])
  File "/usr/lib/python3/dist-packages/urllib3/util/retry.py", line 398, in increment
    raise MaxRetryError(_pool, url, error or ResponseError(cause))
urllib3.exceptions.MaxRetryError: HTTPSConnectionPool(host='ll.thespacedevs.com', port=443): Max retries exceeded with url: /2.0.0/launch/upcoming?mode=list (Caused by SSLError(SSLError(1, '[SSL: SSLV3_ALERT_HANDSHAKE_FAILURE] sslv3 alert handshake failure (_ssl.c:1056)')))

During handling of the above exception, another exception occurred:

Traceback (most recent call last):
  File "print_launches.py", line 6, in <module>
    import get_launches
  File "/home/finn/STM32-Discord-Bot/get_launches.py", line 91, in <module>
    update_launches()
  File "/home/finn/STM32-Discord-Bot/get_launches.py", line 87, in update_launches
    launch_data = get_launch_json()
  File "/home/finn/STM32-Discord-Bot/get_launches.py", line 18, in get_launch_json
    requestData = requests.get('https://ll.thespacedevs.com/2.0.0/launch/upcoming?mode=list')
  File "/usr/lib/python3/dist-packages/requests/api.py", line 75, in get
    return request('get', url, params=params, **kwargs)
  File "/usr/lib/python3/dist-packages/requests/api.py", line 60, in request
    return session.request(method=method, url=url, **kwargs)
  File "/usr/lib/python3/dist-packages/requests/sessions.py", line 533, in request
    resp = self.send(prep, **send_kwargs)
  File "/usr/lib/python3/dist-packages/requests/sessions.py", line 646, in send
    r = adapter.send(request, **kwargs)
  File "/usr/lib/python3/dist-packages/requests/adapters.py", line 514, in send
    raise SSLError(e, request=request)
requests.exceptions.SSLError: HTTPSConnectionPool(host='ll.thespacedevs.com', port=443): Max retries exceeded with url: /2.0.0/launch/upcoming?mode=list (Caused by SSLError(SSLError(1, '[SSL: SSLV3_ALERT_HANDSHAKE_FAILURE] sslv3 alert handshake failure (_ssl.c:1056)')))
Sending Message
Sending Message
Sending Message
Sending Message
Sending Message
Sending Message
Traceback (most recent call last):
  File "/usr/lib/python3/dist-packages/urllib3/connectionpool.py", line 600, in urlopen
    chunked=chunked)
  File "/usr/lib/python3/dist-packages/urllib3/connectionpool.py", line 343, in _make_request
    self._validate_conn(conn)
  File "/usr/lib/python3/dist-packages/urllib3/connectionpool.py", line 841, in _validate_conn
    conn.connect()
  File "/usr/lib/python3/dist-packages/urllib3/connection.py", line 344, in connect
    ssl_context=context)
  File "/usr/lib/python3/dist-packages/urllib3/util/ssl_.py", line 344, in ssl_wrap_socket
    return context.wrap_socket(sock, server_hostname=server_hostname)
  File "/usr/lib/python3.7/ssl.py", line 412, in wrap_socket
    session=session
  File "/usr/lib/python3.7/ssl.py", line 853, in _create
    self.do_handshake()
  File "/usr/lib/python3.7/ssl.py", line 1117, in do_handshake
    self._sslobj.do_handshake()
ssl.SSLError: [SSL: SSLV3_ALERT_HANDSHAKE_FAILURE] sslv3 alert handshake failure (_ssl.c:1056)

During handling of the above exception, another exception occurred:

Traceback (most recent call last):
  File "/usr/lib/python3/dist-packages/requests/adapters.py", line 449, in send
    timeout=timeout
  File "/usr/lib/python3/dist-packages/urllib3/connectionpool.py", line 638, in urlopen
    _stacktrace=sys.exc_info()[2])
  File "/usr/lib/python3/dist-packages/urllib3/util/retry.py", line 398, in increment
    raise MaxRetryError(_pool, url, error or ResponseError(cause))
urllib3.exceptions.MaxRetryError: HTTPSConnectionPool(host='ll.thespacedevs.com', port=443): Max retries exceeded with url: /2.0.0/launch/upcoming?mode=list (Caused by SSLError(SSLError(1, '[SSL: SSLV3_ALERT_HANDSHAKE_FAILURE] sslv3 alert handshake failure (_ssl.c:1056)')))

During handling of the above exception, another exception occurred:

Traceback (most recent call last):
  File "print_launches.py", line 6, in <module>
    import get_launches
  File "/home/finn/STM32-Discord-Bot/get_launches.py", line 91, in <module>
    update_launches()
  File "/home/finn/STM32-Discord-Bot/get_launches.py", line 87, in update_launches
    launch_data = get_launch_json()
  File "/home/finn/STM32-Discord-Bot/get_launches.py", line 18, in get_launch_json
    requestData = requests.get('https://ll.thespacedevs.com/2.0.0/launch/upcoming?mode=list')
  File "/usr/lib/python3/dist-packages/requests/api.py", line 75, in get
    return request('get', url, params=params, **kwargs)
  File "/usr/lib/python3/dist-packages/requests/api.py", line 60, in request
    return session.request(method=method, url=url, **kwargs)
  File "/usr/lib/python3/dist-packages/requests/sessions.py", line 533, in request
    resp = self.send(prep, **send_kwargs)
  File "/usr/lib/python3/dist-packages/requests/sessions.py", line 646, in send
    r = adapter.send(request, **kwargs)
  File "/usr/lib/python3/dist-packages/requests/adapters.py", line 514, in send
    raise SSLError(e, request=request)
requests.exceptions.SSLError: HTTPSConnectionPool(host='ll.thespacedevs.com', port=443): Max retries exceeded with url: /2.0.0/launch/upcoming?mode=list (Caused by SSLError(SSLError(1, '[SSL: SSLV3_ALERT_HANDSHAKE_FAILURE] sslv3 alert handshake failure (_ssl.c:1056)')))
Traceback (most recent call last):
  File "/usr/lib/python3/dist-packages/urllib3/connectionpool.py", line 600, in urlopen
    chunked=chunked)
  File "/usr/lib/python3/dist-packages/urllib3/connectionpool.py", line 343, in _make_request
    self._validate_conn(conn)
  File "/usr/lib/python3/dist-packages/urllib3/connectionpool.py", line 841, in _validate_conn
    conn.connect()
  File "/usr/lib/python3/dist-packages/urllib3/connection.py", line 344, in connect
    ssl_context=context)
  File "/usr/lib/python3/dist-packages/urllib3/util/ssl_.py", line 344, in ssl_wrap_socket
    return context.wrap_socket(sock, server_hostname=server_hostname)
  File "/usr/lib/python3.7/ssl.py", line 412, in wrap_socket
    session=session
  File "/usr/lib/python3.7/ssl.py", line 853, in _create
    self.do_handshake()
  File "/usr/lib/python3.7/ssl.py", line 1117, in do_handshake
    self._sslobj.do_handshake()
ssl.SSLError: [SSL: SSLV3_ALERT_HANDSHAKE_FAILURE] sslv3 alert handshake failure (_ssl.c:1056)

During handling of the above exception, another exception occurred:

Traceback (most recent call last):
  File "/usr/lib/python3/dist-packages/requests/adapters.py", line 449, in send
    timeout=timeout
  File "/usr/lib/python3/dist-packages/urllib3/connectionpool.py", line 638, in urlopen
    _stacktrace=sys.exc_info()[2])
  File "/usr/lib/python3/dist-packages/urllib3/util/retry.py", line 398, in increment
    raise MaxRetryError(_pool, url, error or ResponseError(cause))
urllib3.exceptions.MaxRetryError: HTTPSConnectionPool(host='ll.thespacedevs.com', port=443): Max retries exceeded with url: /2.0.0/launch/upcoming?mode=list (Caused by SSLError(SSLError(1, '[SSL: SSLV3_ALERT_HANDSHAKE_FAILURE] sslv3 alert handshake failure (_ssl.c:1056)')))

During handling of the above exception, another exception occurred:

Traceback (most recent call last):
  File "print_launches.py", line 6, in <module>
    import get_launches
  File "/home/finn/STM32-Discord-Bot/get_launches.py", line 91, in <module>
    update_launches()
  File "/home/finn/STM32-Discord-Bot/get_launches.py", line 87, in update_launches
    launch_data = get_launch_json()
  File "/home/finn/STM32-Discord-Bot/get_launches.py", line 18, in get_launch_json
    requestData = requests.get('https://ll.thespacedevs.com/2.0.0/launch/upcoming?mode=list')
  File "/usr/lib/python3/dist-packages/requests/api.py", line 75, in get
    return request('get', url, params=params, **kwargs)
  File "/usr/lib/python3/dist-packages/requests/api.py", line 60, in request
    return session.request(method=method, url=url, **kwargs)
  File "/usr/lib/python3/dist-packages/requests/sessions.py", line 533, in request
    resp = self.send(prep, **send_kwargs)
  File "/usr/lib/python3/dist-packages/requests/sessions.py", line 646, in send
    r = adapter.send(request, **kwargs)
  File "/usr/lib/python3/dist-packages/requests/adapters.py", line 514, in send
    raise SSLError(e, request=request)
requests.exceptions.SSLError: HTTPSConnectionPool(host='ll.thespacedevs.com', port=443): Max retries exceeded with url: /2.0.0/launch/upcoming?mode=list (Caused by SSLError(SSLError(1, '[SSL: SSLV3_ALERT_HANDSHAKE_FAILURE] sslv3 alert handshake failure (_ssl.c:1056)')))
Sending Message
Sending Message
Sending Message
Sending Message
Sending Message
Sending Message
Sending Message
Sending Message
Sending Message
Sending Message
Sending Message
Sending Message
Sending Message
Sending Message
Sending Message
Sending Message
Sending Message
Traceback (most recent call last):
  File "/usr/lib/python3/dist-packages/urllib3/connectionpool.py", line 600, in urlopen
    chunked=chunked)
  File "/usr/lib/python3/dist-packages/urllib3/connectionpool.py", line 343, in _make_request
    self._validate_conn(conn)
  File "/usr/lib/python3/dist-packages/urllib3/connectionpool.py", line 841, in _validate_conn
    conn.connect()
  File "/usr/lib/python3/dist-packages/urllib3/connection.py", line 344, in connect
    ssl_context=context)
  File "/usr/lib/python3/dist-packages/urllib3/util/ssl_.py", line 344, in ssl_wrap_socket
    return context.wrap_socket(sock, server_hostname=server_hostname)
  File "/usr/lib/python3.7/ssl.py", line 412, in wrap_socket
    session=session
  File "/usr/lib/python3.7/ssl.py", line 853, in _create
    self.do_handshake()
  File "/usr/lib/python3.7/ssl.py", line 1117, in do_handshake
    self._sslobj.do_handshake()
ssl.SSLError: [SSL: SSLV3_ALERT_HANDSHAKE_FAILURE] sslv3 alert handshake failure (_ssl.c:1056)

During handling of the above exception, another exception occurred:

Traceback (most recent call last):
  File "/usr/lib/python3/dist-packages/requests/adapters.py", line 449, in send
    timeout=timeout
  File "/usr/lib/python3/dist-packages/urllib3/connectionpool.py", line 638, in urlopen
    _stacktrace=sys.exc_info()[2])
  File "/usr/lib/python3/dist-packages/urllib3/util/retry.py", line 398, in increment
    raise MaxRetryError(_pool, url, error or ResponseError(cause))
urllib3.exceptions.MaxRetryError: HTTPSConnectionPool(host='ll.thespacedevs.com', port=443): Max retries exceeded with url: /2.0.0/launch/upcoming?mode=list (Caused by SSLError(SSLError(1, '[SSL: SSLV3_ALERT_HANDSHAKE_FAILURE] sslv3 alert handshake failure (_ssl.c:1056)')))

During handling of the above exception, another exception occurred:

Traceback (most recent call last):
  File "print_launches.py", line 6, in <module>
    import get_launches
  File "/home/finn/STM32-Discord-Bot/get_launches.py", line 91, in <module>
    update_launches()
  File "/home/finn/STM32-Discord-Bot/get_launches.py", line 87, in update_launches
    launch_data = get_launch_json()
  File "/home/finn/STM32-Discord-Bot/get_launches.py", line 18, in get_launch_json
    requestData = requests.get('https://ll.thespacedevs.com/2.0.0/launch/upcoming?mode=list')
  File "/usr/lib/python3/dist-packages/requests/api.py", line 75, in get
    return request('get', url, params=params, **kwargs)
  File "/usr/lib/python3/dist-packages/requests/api.py", line 60, in request
    return session.request(method=method, url=url, **kwargs)
  File "/usr/lib/python3/dist-packages/requests/sessions.py", line 533, in request
    resp = self.send(prep, **send_kwargs)
  File "/usr/lib/python3/dist-packages/requests/sessions.py", line 646, in send
    r = adapter.send(request, **kwargs)
  File "/usr/lib/python3/dist-packages/requests/adapters.py", line 514, in send
    raise SSLError(e, request=request)
requests.exceptions.SSLError: HTTPSConnectionPool(host='ll.thespacedevs.com', port=443): Max retries exceeded with url: /2.0.0/launch/upcoming?mode=list (Caused by SSLError(SSLError(1, '[SSL: SSLV3_ALERT_HANDSHAKE_FAILURE] sslv3 alert handshake failure (_ssl.c:1056)')))
Sending Message
Sending Message
Traceback (most recent call last):
  File "/usr/lib/python3/dist-packages/urllib3/connection.py", line 159, in _new_conn
    (self._dns_host, self.port), self.timeout, **extra_kw)
  File "/usr/lib/python3/dist-packages/urllib3/util/connection.py", line 57, in create_connection
    for res in socket.getaddrinfo(host, port, family, socket.SOCK_STREAM):
  File "/usr/lib/python3.7/socket.py", line 748, in getaddrinfo
    for res in _socket.getaddrinfo(host, port, family, type, proto, flags):
socket.gaierror: [Errno -3] Temporary failure in name resolution

During handling of the above exception, another exception occurred:

Traceback (most recent call last):
  File "/usr/lib/python3/dist-packages/urllib3/connectionpool.py", line 600, in urlopen
    chunked=chunked)
  File "/usr/lib/python3/dist-packages/urllib3/connectionpool.py", line 343, in _make_request
    self._validate_conn(conn)
  File "/usr/lib/python3/dist-packages/urllib3/connectionpool.py", line 841, in _validate_conn
    conn.connect()
  File "/usr/lib/python3/dist-packages/urllib3/connection.py", line 301, in connect
    conn = self._new_conn()
  File "/usr/lib/python3/dist-packages/urllib3/connection.py", line 168, in _new_conn
    self, "Failed to establish a new connection: %s" % e)
urllib3.exceptions.NewConnectionError: <urllib3.connection.VerifiedHTTPSConnection object at 0x7f66382ec2e8>: Failed to establish a new connection: [Errno -3] Temporary failure in name resolution

During handling of the above exception, another exception occurred:

Traceback (most recent call last):
  File "/usr/lib/python3/dist-packages/requests/adapters.py", line 449, in send
    timeout=timeout
  File "/usr/lib/python3/dist-packages/urllib3/connectionpool.py", line 638, in urlopen
    _stacktrace=sys.exc_info()[2])
  File "/usr/lib/python3/dist-packages/urllib3/util/retry.py", line 398, in increment
    raise MaxRetryError(_pool, url, error or ResponseError(cause))
urllib3.exceptions.MaxRetryError: HTTPSConnectionPool(host='ll.thespacedevs.com', port=443): Max retries exceeded with url: /2.0.0/launch/upcoming?mode=list (Caused by NewConnectionError('<urllib3.connection.VerifiedHTTPSConnection object at 0x7f66382ec2e8>: Failed to establish a new connection: [Errno -3] Temporary failure in name resolution'))

During handling of the above exception, another exception occurred:

Traceback (most recent call last):
  File "print_launches.py", line 6, in <module>
    import get_launches
  File "/home/finn/STM32-Discord-Bot/get_launches.py", line 91, in <module>
    update_launches()
  File "/home/finn/STM32-Discord-Bot/get_launches.py", line 87, in update_launches
    launch_data = get_launch_json()
  File "/home/finn/STM32-Discord-Bot/get_launches.py", line 18, in get_launch_json
    requestData = requests.get('https://ll.thespacedevs.com/2.0.0/launch/upcoming?mode=list')
  File "/usr/lib/python3/dist-packages/requests/api.py", line 75, in get
    return request('get', url, params=params, **kwargs)
  File "/usr/lib/python3/dist-packages/requests/api.py", line 60, in request
    return session.request(method=method, url=url, **kwargs)
  File "/usr/lib/python3/dist-packages/requests/sessions.py", line 533, in request
    resp = self.send(prep, **send_kwargs)
  File "/usr/lib/python3/dist-packages/requests/sessions.py", line 646, in send
    r = adapter.send(request, **kwargs)
  File "/usr/lib/python3/dist-packages/requests/adapters.py", line 516, in send
    raise ConnectionError(e, request=request)
requests.exceptions.ConnectionError: HTTPSConnectionPool(host='ll.thespacedevs.com', port=443): Max retries exceeded with url: /2.0.0/launch/upcoming?mode=list (Caused by NewConnectionError('<urllib3.connection.VerifiedHTTPSConnection object at 0x7f66382ec2e8>: Failed to establish a new connection: [Errno -3] Temporary failure in name resolution'))
Sending Message
Sending Message
Sending Message
Sending Message
Sending Message
Sending Message
Sending Message
Traceback (most recent call last):
  File "/usr/lib/python3/dist-packages/urllib3/connectionpool.py", line 600, in urlopen
    chunked=chunked)
  File "/usr/lib/python3/dist-packages/urllib3/connectionpool.py", line 343, in _make_request
    self._validate_conn(conn)
  File "/usr/lib/python3/dist-packages/urllib3/connectionpool.py", line 841, in _validate_conn
    conn.connect()
  File "/usr/lib/python3/dist-packages/urllib3/connection.py", line 344, in connect
    ssl_context=context)
  File "/usr/lib/python3/dist-packages/urllib3/util/ssl_.py", line 344, in ssl_wrap_socket
    return context.wrap_socket(sock, server_hostname=server_hostname)
  File "/usr/lib/python3.7/ssl.py", line 412, in wrap_socket
    session=session
  File "/usr/lib/python3.7/ssl.py", line 853, in _create
    self.do_handshake()
  File "/usr/lib/python3.7/ssl.py", line 1117, in do_handshake
    self._sslobj.do_handshake()
ssl.SSLError: [SSL: SSLV3_ALERT_HANDSHAKE_FAILURE] sslv3 alert handshake failure (_ssl.c:1056)

During handling of the above exception, another exception occurred:

Traceback (most recent call last):
  File "/usr/lib/python3/dist-packages/requests/adapters.py", line 449, in send
    timeout=timeout
  File "/usr/lib/python3/dist-packages/urllib3/connectionpool.py", line 638, in urlopen
    _stacktrace=sys.exc_info()[2])
  File "/usr/lib/python3/dist-packages/urllib3/util/retry.py", line 398, in increment
    raise MaxRetryError(_pool, url, error or ResponseError(cause))
urllib3.exceptions.MaxRetryError: HTTPSConnectionPool(host='ll.thespacedevs.com', port=443): Max retries exceeded with url: /2.0.0/launch/upcoming?mode=list (Caused by SSLError(SSLError(1, '[SSL: SSLV3_ALERT_HANDSHAKE_FAILURE] sslv3 alert handshake failure (_ssl.c:1056)')))

During handling of the above exception, another exception occurred:

Traceback (most recent call last):
  File "print_launches.py", line 6, in <module>
    import get_launches
  File "/home/finn/STM32-Discord-Bot/get_launches.py", line 91, in <module>
    update_launches()
  File "/home/finn/STM32-Discord-Bot/get_launches.py", line 87, in update_launches
    launch_data = get_launch_json()
  File "/home/finn/STM32-Discord-Bot/get_launches.py", line 18, in get_launch_json
    requestData = requests.get('https://ll.thespacedevs.com/2.0.0/launch/upcoming?mode=list')
  File "/usr/lib/python3/dist-packages/requests/api.py", line 75, in get
    return request('get', url, params=params, **kwargs)
  File "/usr/lib/python3/dist-packages/requests/api.py", line 60, in request
    return session.request(method=method, url=url, **kwargs)
  File "/usr/lib/python3/dist-packages/requests/sessions.py", line 533, in request
    resp = self.send(prep, **send_kwargs)
  File "/usr/lib/python3/dist-packages/requests/sessions.py", line 646, in send
    r = adapter.send(request, **kwargs)
  File "/usr/lib/python3/dist-packages/requests/adapters.py", line 514, in send
    raise SSLError(e, request=request)
requests.exceptions.SSLError: HTTPSConnectionPool(host='ll.thespacedevs.com', port=443): Max retries exceeded with url: /2.0.0/launch/upcoming?mode=list (Caused by SSLError(SSLError(1, '[SSL: SSLV3_ALERT_HANDSHAKE_FAILURE] sslv3 alert handshake failure (_ssl.c:1056)')))
Sending Message
Sending Message
Sending Message
Sending Message
Sending Message
Sending Message
Sending Message
Sending Message
Sending Message
Sending Message
Sending Message
Sending Message
Sending Message
Sending Message
Sending Message
Sending Message
Sending Message
Sending Message
Sending Message
Sending Message
Sending Message
Traceback (most recent call last):
  File "/usr/lib/python3/dist-packages/urllib3/connectionpool.py", line 600, in urlopen
    chunked=chunked)
  File "/usr/lib/python3/dist-packages/urllib3/connectionpool.py", line 343, in _make_request
    self._validate_conn(conn)
  File "/usr/lib/python3/dist-packages/urllib3/connectionpool.py", line 841, in _validate_conn
    conn.connect()
  File "/usr/lib/python3/dist-packages/urllib3/connection.py", line 344, in connect
    ssl_context=context)
  File "/usr/lib/python3/dist-packages/urllib3/util/ssl_.py", line 344, in ssl_wrap_socket
    return context.wrap_socket(sock, server_hostname=server_hostname)
  File "/usr/lib/python3.7/ssl.py", line 412, in wrap_socket
    session=session
  File "/usr/lib/python3.7/ssl.py", line 853, in _create
    self.do_handshake()
  File "/usr/lib/python3.7/ssl.py", line 1117, in do_handshake
    self._sslobj.do_handshake()
ssl.SSLError: [SSL: SSLV3_ALERT_HANDSHAKE_FAILURE] sslv3 alert handshake failure (_ssl.c:1056)

During handling of the above exception, another exception occurred:

Traceback (most recent call last):
  File "/usr/lib/python3/dist-packages/requests/adapters.py", line 449, in send
    timeout=timeout
  File "/usr/lib/python3/dist-packages/urllib3/connectionpool.py", line 638, in urlopen
    _stacktrace=sys.exc_info()[2])
  File "/usr/lib/python3/dist-packages/urllib3/util/retry.py", line 398, in increment
    raise MaxRetryError(_pool, url, error or ResponseError(cause))
urllib3.exceptions.MaxRetryError: HTTPSConnectionPool(host='ll.thespacedevs.com', port=443): Max retries exceeded with url: /2.0.0/launch/upcoming?mode=list (Caused by SSLError(SSLError(1, '[SSL: SSLV3_ALERT_HANDSHAKE_FAILURE] sslv3 alert handshake failure (_ssl.c:1056)')))

During handling of the above exception, another exception occurred:

Traceback (most recent call last):
  File "print_launches.py", line 6, in <module>
    import get_launches
  File "/home/finn/STM32-Discord-Bot/get_launches.py", line 91, in <module>
    update_launches()
  File "/home/finn/STM32-Discord-Bot/get_launches.py", line 87, in update_launches
    launch_data = get_launch_json()
  File "/home/finn/STM32-Discord-Bot/get_launches.py", line 18, in get_launch_json
    requestData = requests.get('https://ll.thespacedevs.com/2.0.0/launch/upcoming?mode=list')
  File "/usr/lib/python3/dist-packages/requests/api.py", line 75, in get
    return request('get', url, params=params, **kwargs)
  File "/usr/lib/python3/dist-packages/requests/api.py", line 60, in request
    return session.request(method=method, url=url, **kwargs)
  File "/usr/lib/python3/dist-packages/requests/sessions.py", line 533, in request
    resp = self.send(prep, **send_kwargs)
  File "/usr/lib/python3/dist-packages/requests/sessions.py", line 646, in send
    r = adapter.send(request, **kwargs)
  File "/usr/lib/python3/dist-packages/requests/adapters.py", line 514, in send
    raise SSLError(e, request=request)
requests.exceptions.SSLError: HTTPSConnectionPool(host='ll.thespacedevs.com', port=443): Max retries exceeded with url: /2.0.0/launch/upcoming?mode=list (Caused by SSLError(SSLError(1, '[SSL: SSLV3_ALERT_HANDSHAKE_FAILURE] sslv3 alert handshake failure (_ssl.c:1056)')))
Sending Message
Sending Message
Sending Message
Sending Message
Sending Message
Sending Message
Sending Message
Sending Message
Sending Message
Sending Message
Sending Message
Sending Message
Traceback (most recent call last):
  File "/usr/lib/python3/dist-packages/urllib3/connectionpool.py", line 600, in urlopen
    chunked=chunked)
  File "/usr/lib/python3/dist-packages/urllib3/connectionpool.py", line 343, in _make_request
    self._validate_conn(conn)
  File "/usr/lib/python3/dist-packages/urllib3/connectionpool.py", line 841, in _validate_conn
    conn.connect()
  File "/usr/lib/python3/dist-packages/urllib3/connection.py", line 344, in connect
    ssl_context=context)
  File "/usr/lib/python3/dist-packages/urllib3/util/ssl_.py", line 344, in ssl_wrap_socket
    return context.wrap_socket(sock, server_hostname=server_hostname)
  File "/usr/lib/python3.7/ssl.py", line 412, in wrap_socket
    session=session
  File "/usr/lib/python3.7/ssl.py", line 853, in _create
    self.do_handshake()
  File "/usr/lib/python3.7/ssl.py", line 1117, in do_handshake
    self._sslobj.do_handshake()
ssl.SSLError: [SSL: SSLV3_ALERT_HANDSHAKE_FAILURE] sslv3 alert handshake failure (_ssl.c:1056)

During handling of the above exception, another exception occurred:

Traceback (most recent call last):
  File "/usr/lib/python3/dist-packages/requests/adapters.py", line 449, in send
    timeout=timeout
  File "/usr/lib/python3/dist-packages/urllib3/connectionpool.py", line 638, in urlopen
    _stacktrace=sys.exc_info()[2])
  File "/usr/lib/python3/dist-packages/urllib3/util/retry.py", line 398, in increment
    raise MaxRetryError(_pool, url, error or ResponseError(cause))
urllib3.exceptions.MaxRetryError: HTTPSConnectionPool(host='ll.thespacedevs.com', port=443): Max retries exceeded with url: /2.0.0/launch/upcoming?mode=list (Caused by SSLError(SSLError(1, '[SSL: SSLV3_ALERT_HANDSHAKE_FAILURE] sslv3 alert handshake failure (_ssl.c:1056)')))

During handling of the above exception, another exception occurred:

Traceback (most recent call last):
  File "print_launches.py", line 6, in <module>
    import get_launches
  File "/home/finn/STM32-Discord-Bot/get_launches.py", line 91, in <module>
    update_launches()
  File "/home/finn/STM32-Discord-Bot/get_launches.py", line 87, in update_launches
    launch_data = get_launch_json()
  File "/home/finn/STM32-Discord-Bot/get_launches.py", line 18, in get_launch_json
    requestData = requests.get('https://ll.thespacedevs.com/2.0.0/launch/upcoming?mode=list')
  File "/usr/lib/python3/dist-packages/requests/api.py", line 75, in get
    return request('get', url, params=params, **kwargs)
  File "/usr/lib/python3/dist-packages/requests/api.py", line 60, in request
    return session.request(method=method, url=url, **kwargs)
  File "/usr/lib/python3/dist-packages/requests/sessions.py", line 533, in request
    resp = self.send(prep, **send_kwargs)
  File "/usr/lib/python3/dist-packages/requests/sessions.py", line 646, in send
    r = adapter.send(request, **kwargs)
  File "/usr/lib/python3/dist-packages/requests/adapters.py", line 514, in send
    raise SSLError(e, request=request)
requests.exceptions.SSLError: HTTPSConnectionPool(host='ll.thespacedevs.com', port=443): Max retries exceeded with url: /2.0.0/launch/upcoming?mode=list (Caused by SSLError(SSLError(1, '[SSL: SSLV3_ALERT_HANDSHAKE_FAILURE] sslv3 alert handshake failure (_ssl.c:1056)')))
Sending Message
Sending Message
Sending Message
Sending Message
Sending Message
Sending Message
Sending Message
Sending Message
Sending Message
Sending Message
Sending Message
Sending Message
Sending Message
Sending Message
Sending Message
Sending Message
Sending Message
Sending Message
Sending Message
Sending Message
Sending Message
Ignoring exception in on_ready
Traceback (most recent call last):
  File "/home/finn/.local/lib/python3.7/site-packages/discord/client.py", line 343, in _run_event
    await coro(*args, **kwargs)
  File "print_launches.py", line 23, in on_ready
    await channel.send(message)
  File "/home/finn/.local/lib/python3.7/site-packages/discord/abc.py", line 937, in send
    message_reference=reference)
  File "/home/finn/.local/lib/python3.7/site-packages/discord/http.py", line 247, in request
    raise HTTPException(r, data)
discord.errors.HTTPException: 504 Gateway Time-out (error code: 0): <!DOCTYPE html>
<!--[if lt IE 7]> <html class="no-js ie6 oldie" lang="en-US"> <![endif]-->
<!--[if IE 7]>    <html class="no-js ie7 oldie" lang="en-US"> <![endif]-->
<!--[if IE 8]>    <html class="no-js ie8 oldie" lang="en-US"> <![endif]-->
<!--[if gt IE 8]><!--> <html class="no-js" lang="en-US"> <!--<![endif]-->
<head>


<title>discord.com | 504: Gateway time-out</title>
<meta charset="UTF-8" />
<meta http-equiv="Content-Type" content="text/html; charset=UTF-8" />
<meta http-equiv="X-UA-Compatible" content="IE=Edge" />
<meta name="robots" content="noindex, nofollow" />
<meta name="viewport" content="width=device-width,initial-scale=1" />
<link rel="stylesheet" id="cf_styles-css" href="/cdn-cgi/styles/main.css" />


</head>
<body>
<div id="cf-wrapper">

    

    <div id="cf-error-details" class="p-0">
        <header class="mx-auto pt-10 lg:pt-6 lg:px-8 w-240 lg:w-full mb-8">
            <h1 class="inline-block sm:block sm:mb-2 font-light text-60 lg:text-4xl text-black-dark leading-tight mr-2">
              
              <span class="inline-block">Gateway time-out</span>
              <span class="code-label">Error code 504</span>
            </h1>
            <div>
               Visit <a href="https://www.cloudflare.com/5xx-error-landing?utm_source=errorcode_504&utm_campaign=discord.com" target="_blank" rel="noopener noreferrer">cloudflare.com</a> for more information.
            </div>
            <div class="mt-3">2022-09-15 20:22:35 UTC</div>
        </header>
        
        <div class="my-8 bg-gradient-gray">
            <div class="w-240 lg:w-full mx-auto">
                <div class="clearfix md:px-8">
                  
<div id="cf-browser-status" class=" relative w-1/3 md:w-full py-15 md:p-0 md:py-8 md:text-left md:border-solid md:border-0 md:border-b md:border-gray-400 overflow-hidden float-left md:float-none text-center">
  <div class="relative mb-10 md:m-0">
    
    <span class="cf-icon-browser block md:hidden h-20 bg-center bg-no-repeat"></span>
    <span class="cf-icon-ok w-12 h-12 absolute left-1/2 md:left-auto md:right-0 md:top-0 -ml-6 -bottom-4"></span>
    
  </div>
  <span class="md:block w-full truncate">You</span>
  <h3 class="md:inline-block mt-3 md:mt-0 text-2xl text-gray-600 font-light leading-1.3">
    
    Browser
    
  </h3>
  <span class="leading-1.3 text-2xl text-green-success">Working</span>
</div>

<div id="cf-cloudflare-status" class=" relative w-1/3 md:w-full py-15 md:p-0 md:py-8 md:text-left md:border-solid md:border-0 md:border-b md:border-gray-400 overflow-hidden float-left md:float-none text-center">
  <div class="relative mb-10 md:m-0">
    <a href="https://www.cloudflare.com/5xx-error-landing?utm_source=errorcode_504&utm_campaign=discord.com" target="_blank" rel="noopener noreferrer">
    <span class="cf-icon-cloud block md:hidden h-20 bg-center bg-no-repeat"></span>
    <span class="cf-icon-ok w-12 h-12 absolute left-1/2 md:left-auto md:right-0 md:top-0 -ml-6 -bottom-4"></span>
    </a>
  </div>
  <span class="md:block w-full truncate">Frankfurt</span>
  <h3 class="md:inline-block mt-3 md:mt-0 text-2xl text-gray-600 font-light leading-1.3">
    <a href="https://www.cloudflare.com/5xx-error-landing?utm_source=errorcode_504&utm_campaign=discord.com" target="_blank" rel="noopener noreferrer">
    Cloudflare
    </a>
  </h3>
  <span class="leading-1.3 text-2xl text-green-success">Working</span>
</div>

<div id="cf-host-status" class="cf-error-source relative w-1/3 md:w-full py-15 md:p-0 md:py-8 md:text-left md:border-solid md:border-0 md:border-b md:border-gray-400 overflow-hidden float-left md:float-none text-center">
  <div class="relative mb-10 md:m-0">
    
    <span class="cf-icon-server block md:hidden h-20 bg-center bg-no-repeat"></span>
    <span class="cf-icon-error w-12 h-12 absolute left-1/2 md:left-auto md:right-0 md:top-0 -ml-6 -bottom-4"></span>
    
  </div>
  <span class="md:block w-full truncate">discord.com</span>
  <h3 class="md:inline-block mt-3 md:mt-0 text-2xl text-gray-600 font-light leading-1.3">
    
    Host
    
  </h3>
  <span class="leading-1.3 text-2xl text-red-error">Error</span>
</div>

                </div>
              
            </div>
        </div>

        <div class="w-240 lg:w-full mx-auto mb-8 lg:px-8">
            <div class="clearfix">
                <div class="w-1/2 md:w-full float-left pr-6 md:pb-10 md:pr-0 leading-relaxed">
                    <h2 class="text-3xl font-normal leading-1.3 mb-4">What happened?</h2>
                    <p>The web server reported a gateway time-out error.</p>
                </div>
              
                <div class="w-1/2 md:w-full float-left leading-relaxed">
                    <h2 class="text-3xl font-normal leading-1.3 mb-4">What can I do?</h2>
                    <p class="mb-6">Please try again in a few minutes.</p>
                </div>
            </div>
              
        </div>

        <div class="cf-error-footer cf-wrapper w-240 lg:w-full py-10 sm:py-4 sm:px-8 mx-auto text-center sm:text-left border-solid border-0 border-t border-gray-300">
  <p class="text-13">
    <span class="cf-footer-item sm:block sm:mb-1">Cloudflare Ray ID: <strong class="font-semibold">74b4128cff359290</strong></span>
    <span class="cf-footer-separator sm:hidden">&bull;</span>
    <span id="cf-footer-item-ip" class="cf-footer-item hidden sm:block sm:mb-1">
      Your IP:
      <button type="button" id="cf-footer-ip-reveal" class="cf-footer-ip-reveal-btn">Click to reveal</button>
      <span class="hidden" id="cf-footer-ip">193.196.52.91</span>
      <span class="cf-footer-separator sm:hidden">&bull;</span>
    </span>
    <span class="cf-footer-item sm:block sm:mb-1"><span>Performance &amp; security by</span> <a rel="noopener noreferrer" href="https://www.cloudflare.com/5xx-error-landing?utm_source=errorcode_504&utm_campaign=discord.com" id="brand_link" target="_blank">Cloudflare</a></span>
    
  </p>
  <script>(function(){function d(){var b=a.getElementById("cf-footer-item-ip"),c=a.getElementById("cf-footer-ip-reveal");b&&"classList"in b&&(b.classList.remove("hidden"),c.addEventListener("click",function(){c.classList.add("hidden");a.getElementById("cf-footer-ip").classList.remove("hidden")}))}var a=document;document.addEventListener&&a.addEventListener("DOMContentLoaded",d)})();</script>
</div><!-- /.error-footer -->


    </div>
</div>
</body>
</html>


Sending Message
